[2023-06-21 14:11:09,239] {taskinstance.py:1159} INFO - Dependencies all met for <TaskInstance: dados_climaticos.criar_pasta scheduled__2023-02-20T00:00:00+00:00 [queued]>
[2023-06-21 14:11:09,243] {taskinstance.py:1159} INFO - Dependencies all met for <TaskInstance: dados_climaticos.criar_pasta scheduled__2023-02-20T00:00:00+00:00 [queued]>
[2023-06-21 14:11:09,243] {taskinstance.py:1356} INFO - 
--------------------------------------------------------------------------------
[2023-06-21 14:11:09,243] {taskinstance.py:1357} INFO - Starting attempt 1 of 1
[2023-06-21 14:11:09,244] {taskinstance.py:1358} INFO - 
--------------------------------------------------------------------------------
[2023-06-21 14:11:09,255] {taskinstance.py:1377} INFO - Executing <Task(BashOperator): criar_pasta> on 2023-02-20 00:00:00+00:00
[2023-06-21 14:11:09,258] {standard_task_runner.py:52} INFO - Started process 87369 to run task
[2023-06-21 14:11:09,261] {standard_task_runner.py:79} INFO - Running: ['airflow', 'tasks', 'run', 'dados_climaticos', 'criar_pasta', 'scheduled__2023-02-20T00:00:00+00:00', '--job-id', '47', '--raw', '--subdir', 'DAGS_FOLDER/dados_climaticos.py', '--cfg-path', '/tmp/tmpnfs019bb', '--error-file', '/tmp/tmppkqep2bv']
[2023-06-21 14:11:09,262] {standard_task_runner.py:80} INFO - Job 47: Subtask criar_pasta
[2023-06-21 14:11:09,294] {task_command.py:370} INFO - Running <TaskInstance: dados_climaticos.criar_pasta scheduled__2023-02-20T00:00:00+00:00 [running]> on host alura
[2023-06-21 14:11:09,312] {taskinstance.py:1889} ERROR - Task failed with exception
Traceback (most recent call last):
  File "/home/gilmar/Documentos/airflowalura/venv/lib/python3.9/site-packages/airflow/models/taskinstance.py", line 1451, in _run_raw_task
    self._execute_task_with_callbacks(context, test_mode)
  File "/home/gilmar/Documentos/airflowalura/venv/lib/python3.9/site-packages/airflow/models/taskinstance.py", line 1555, in _execute_task_with_callbacks
    task_orig = self.render_templates(context=context)
  File "/home/gilmar/Documentos/airflowalura/venv/lib/python3.9/site-packages/airflow/models/taskinstance.py", line 2212, in render_templates
    rendered_task = self.task.render_template_fields(context)
  File "/home/gilmar/Documentos/airflowalura/venv/lib/python3.9/site-packages/airflow/models/baseoperator.py", line 1185, in render_template_fields
    self._do_render_template_fields(self, self.template_fields, context, jinja_env, set())
  File "/home/gilmar/Documentos/airflowalura/venv/lib/python3.9/site-packages/airflow/utils/session.py", line 71, in wrapper
    return func(*args, session=session, **kwargs)
  File "/home/gilmar/Documentos/airflowalura/venv/lib/python3.9/site-packages/airflow/models/abstractoperator.py", line 344, in _do_render_template_fields
    rendered_content = self.render_template(
  File "/home/gilmar/Documentos/airflowalura/venv/lib/python3.9/site-packages/airflow/models/abstractoperator.py", line 387, in render_template
    template = jinja_env.from_string(value)
  File "/home/gilmar/Documentos/airflowalura/venv/lib/python3.9/site-packages/jinja2/environment.py", line 1092, in from_string
    return cls.from_code(self, self.compile(source), gs, None)
  File "/home/gilmar/Documentos/airflowalura/venv/lib/python3.9/site-packages/jinja2/environment.py", line 757, in compile
    self.handle_exception(source=source_hint)
  File "/home/gilmar/Documentos/airflowalura/venv/lib/python3.9/site-packages/jinja2/environment.py", line 925, in handle_exception
    raise rewrite_traceback_stack(source=source)
  File "<unknown>", line 1, in template
jinja2.exceptions.TemplateSyntaxError: unexpected end of template, expected ','.
[2023-06-21 14:11:09,316] {taskinstance.py:1395} INFO - Marking task as FAILED. dag_id=dados_climaticos, task_id=criar_pasta, execution_date=20230220T000000, start_date=20230621T171109, end_date=20230621T171109
[2023-06-21 14:11:09,325] {standard_task_runner.py:92} ERROR - Failed to execute job 47 for task criar_pasta (unexpected end of template, expected ','.; 87369)
[2023-06-21 14:11:09,357] {local_task_job.py:156} INFO - Task exited with return code 1
[2023-06-21 14:11:09,380] {local_task_job.py:273} INFO - 0 downstream tasks scheduled from follow-on schedule check
[2023-06-21 14:16:17,643] {taskinstance.py:1159} INFO - Dependencies all met for <TaskInstance: dados_climaticos.criar_pasta scheduled__2023-02-20T00:00:00+00:00 [queued]>
[2023-06-21 14:16:17,647] {taskinstance.py:1159} INFO - Dependencies all met for <TaskInstance: dados_climaticos.criar_pasta scheduled__2023-02-20T00:00:00+00:00 [queued]>
[2023-06-21 14:16:17,647] {taskinstance.py:1356} INFO - 
--------------------------------------------------------------------------------
[2023-06-21 14:16:17,647] {taskinstance.py:1357} INFO - Starting attempt 1 of 1
[2023-06-21 14:16:17,647] {taskinstance.py:1358} INFO - 
--------------------------------------------------------------------------------
[2023-06-21 14:16:17,656] {taskinstance.py:1377} INFO - Executing <Task(BashOperator): criar_pasta> on 2023-02-20 00:00:00+00:00
[2023-06-21 14:16:17,659] {standard_task_runner.py:52} INFO - Started process 87904 to run task
[2023-06-21 14:16:17,663] {standard_task_runner.py:79} INFO - Running: ['airflow', 'tasks', 'run', 'dados_climaticos', 'criar_pasta', 'scheduled__2023-02-20T00:00:00+00:00', '--job-id', '47', '--raw', '--subdir', 'DAGS_FOLDER/dados_climaticos.py', '--cfg-path', '/tmp/tmp52z4vata', '--error-file', '/tmp/tmplhhvutc3']
[2023-06-21 14:16:17,664] {standard_task_runner.py:80} INFO - Job 47: Subtask criar_pasta
[2023-06-21 14:16:17,695] {task_command.py:370} INFO - Running <TaskInstance: dados_climaticos.criar_pasta scheduled__2023-02-20T00:00:00+00:00 [running]> on host alura
[2023-06-21 14:16:17,714] {taskinstance.py:1889} ERROR - Task failed with exception
Traceback (most recent call last):
  File "/home/gilmar/Documentos/airflowalura/venv/lib/python3.9/site-packages/airflow/models/taskinstance.py", line 1451, in _run_raw_task
    self._execute_task_with_callbacks(context, test_mode)
  File "/home/gilmar/Documentos/airflowalura/venv/lib/python3.9/site-packages/airflow/models/taskinstance.py", line 1555, in _execute_task_with_callbacks
    task_orig = self.render_templates(context=context)
  File "/home/gilmar/Documentos/airflowalura/venv/lib/python3.9/site-packages/airflow/models/taskinstance.py", line 2212, in render_templates
    rendered_task = self.task.render_template_fields(context)
  File "/home/gilmar/Documentos/airflowalura/venv/lib/python3.9/site-packages/airflow/models/baseoperator.py", line 1185, in render_template_fields
    self._do_render_template_fields(self, self.template_fields, context, jinja_env, set())
  File "/home/gilmar/Documentos/airflowalura/venv/lib/python3.9/site-packages/airflow/utils/session.py", line 71, in wrapper
    return func(*args, session=session, **kwargs)
  File "/home/gilmar/Documentos/airflowalura/venv/lib/python3.9/site-packages/airflow/models/abstractoperator.py", line 344, in _do_render_template_fields
    rendered_content = self.render_template(
  File "/home/gilmar/Documentos/airflowalura/venv/lib/python3.9/site-packages/airflow/models/abstractoperator.py", line 387, in render_template
    template = jinja_env.from_string(value)
  File "/home/gilmar/Documentos/airflowalura/venv/lib/python3.9/site-packages/jinja2/environment.py", line 1092, in from_string
    return cls.from_code(self, self.compile(source), gs, None)
  File "/home/gilmar/Documentos/airflowalura/venv/lib/python3.9/site-packages/jinja2/environment.py", line 757, in compile
    self.handle_exception(source=source_hint)
  File "/home/gilmar/Documentos/airflowalura/venv/lib/python3.9/site-packages/jinja2/environment.py", line 925, in handle_exception
    raise rewrite_traceback_stack(source=source)
  File "<unknown>", line 1, in template
jinja2.exceptions.TemplateSyntaxError: unexpected end of template, expected ','.
[2023-06-21 14:16:17,719] {taskinstance.py:1395} INFO - Marking task as FAILED. dag_id=dados_climaticos, task_id=criar_pasta, execution_date=20230220T000000, start_date=20230621T171617, end_date=20230621T171617
[2023-06-21 14:16:17,729] {standard_task_runner.py:92} ERROR - Failed to execute job 47 for task criar_pasta (unexpected end of template, expected ','.; 87904)
[2023-06-21 14:16:17,758] {local_task_job.py:156} INFO - Task exited with return code 1
[2023-06-21 14:16:17,779] {local_task_job.py:273} INFO - 0 downstream tasks scheduled from follow-on schedule check
