[2023-06-21 13:52:18,113] {taskinstance.py:1159} INFO - Dependencies all met for <TaskInstance: dados_climaticos.criar_pasta scheduled__2023-05-29T00:00:00+00:00 [queued]>
[2023-06-21 13:52:18,117] {taskinstance.py:1159} INFO - Dependencies all met for <TaskInstance: dados_climaticos.criar_pasta scheduled__2023-05-29T00:00:00+00:00 [queued]>
[2023-06-21 13:52:18,117] {taskinstance.py:1356} INFO - 
--------------------------------------------------------------------------------
[2023-06-21 13:52:18,118] {taskinstance.py:1357} INFO - Starting attempt 1 of 1
[2023-06-21 13:52:18,118] {taskinstance.py:1358} INFO - 
--------------------------------------------------------------------------------
[2023-06-21 13:52:18,128] {taskinstance.py:1377} INFO - Executing <Task(BashOperator): criar_pasta> on 2023-05-29 00:00:00+00:00
[2023-06-21 13:52:18,131] {standard_task_runner.py:52} INFO - Started process 85535 to run task
[2023-06-21 13:52:18,136] {standard_task_runner.py:79} INFO - Running: ['airflow', 'tasks', 'run', 'dados_climaticos', 'criar_pasta', 'scheduled__2023-05-29T00:00:00+00:00', '--job-id', '14', '--raw', '--subdir', 'DAGS_FOLDER/dados_climaticos.py', '--cfg-path', '/tmp/tmpnn90_bbp', '--error-file', '/tmp/tmp8kl24kmk']
[2023-06-21 13:52:18,137] {standard_task_runner.py:80} INFO - Job 14: Subtask criar_pasta
[2023-06-21 13:52:18,182] {task_command.py:370} INFO - Running <TaskInstance: dados_climaticos.criar_pasta scheduled__2023-05-29T00:00:00+00:00 [running]> on host alura
[2023-06-21 13:52:18,207] {taskinstance.py:1889} ERROR - Task failed with exception
Traceback (most recent call last):
  File "/home/gilmar/Documentos/airflowalura/venv/lib/python3.9/site-packages/airflow/models/taskinstance.py", line 1451, in _run_raw_task
    self._execute_task_with_callbacks(context, test_mode)
  File "/home/gilmar/Documentos/airflowalura/venv/lib/python3.9/site-packages/airflow/models/taskinstance.py", line 1555, in _execute_task_with_callbacks
    task_orig = self.render_templates(context=context)
  File "/home/gilmar/Documentos/airflowalura/venv/lib/python3.9/site-packages/airflow/models/taskinstance.py", line 2212, in render_templates
    rendered_task = self.task.render_template_fields(context)
  File "/home/gilmar/Documentos/airflowalura/venv/lib/python3.9/site-packages/airflow/models/baseoperator.py", line 1185, in render_template_fields
    self._do_render_template_fields(self, self.template_fields, context, jinja_env, set())
  File "/home/gilmar/Documentos/airflowalura/venv/lib/python3.9/site-packages/airflow/utils/session.py", line 71, in wrapper
    return func(*args, session=session, **kwargs)
  File "/home/gilmar/Documentos/airflowalura/venv/lib/python3.9/site-packages/airflow/models/abstractoperator.py", line 344, in _do_render_template_fields
    rendered_content = self.render_template(
  File "/home/gilmar/Documentos/airflowalura/venv/lib/python3.9/site-packages/airflow/models/abstractoperator.py", line 387, in render_template
    template = jinja_env.from_string(value)
  File "/home/gilmar/Documentos/airflowalura/venv/lib/python3.9/site-packages/jinja2/environment.py", line 1092, in from_string
    return cls.from_code(self, self.compile(source), gs, None)
  File "/home/gilmar/Documentos/airflowalura/venv/lib/python3.9/site-packages/jinja2/environment.py", line 757, in compile
    self.handle_exception(source=source_hint)
  File "/home/gilmar/Documentos/airflowalura/venv/lib/python3.9/site-packages/jinja2/environment.py", line 925, in handle_exception
    raise rewrite_traceback_stack(source=source)
  File "<unknown>", line 1, in template
jinja2.exceptions.TemplateSyntaxError: unexpected end of template, expected ','.
[2023-06-21 13:52:18,211] {taskinstance.py:1395} INFO - Marking task as FAILED. dag_id=dados_climaticos, task_id=criar_pasta, execution_date=20230529T000000, start_date=20230621T165218, end_date=20230621T165218
[2023-06-21 13:52:18,220] {standard_task_runner.py:92} ERROR - Failed to execute job 14 for task criar_pasta (unexpected end of template, expected ','.; 85535)
[2023-06-21 13:52:18,231] {local_task_job.py:156} INFO - Task exited with return code 1
[2023-06-21 13:52:18,260] {local_task_job.py:273} INFO - 0 downstream tasks scheduled from follow-on schedule check
[2023-06-21 14:04:52,522] {taskinstance.py:1159} INFO - Dependencies all met for <TaskInstance: dados_climaticos.criar_pasta scheduled__2023-05-29T00:00:00+00:00 [queued]>
[2023-06-21 14:04:52,526] {taskinstance.py:1159} INFO - Dependencies all met for <TaskInstance: dados_climaticos.criar_pasta scheduled__2023-05-29T00:00:00+00:00 [queued]>
[2023-06-21 14:04:52,526] {taskinstance.py:1356} INFO - 
--------------------------------------------------------------------------------
[2023-06-21 14:04:52,526] {taskinstance.py:1357} INFO - Starting attempt 1 of 1
[2023-06-21 14:04:52,526] {taskinstance.py:1358} INFO - 
--------------------------------------------------------------------------------
[2023-06-21 14:04:52,536] {taskinstance.py:1377} INFO - Executing <Task(BashOperator): criar_pasta> on 2023-05-29 00:00:00+00:00
[2023-06-21 14:04:52,539] {standard_task_runner.py:52} INFO - Started process 86783 to run task
[2023-06-21 14:04:52,542] {standard_task_runner.py:79} INFO - Running: ['airflow', 'tasks', 'run', 'dados_climaticos', 'criar_pasta', 'scheduled__2023-05-29T00:00:00+00:00', '--job-id', '21', '--raw', '--subdir', 'DAGS_FOLDER/dados_climaticos.py', '--cfg-path', '/tmp/tmpfx3h5bnb', '--error-file', '/tmp/tmplrqqlnsz']
[2023-06-21 14:04:52,543] {standard_task_runner.py:80} INFO - Job 21: Subtask criar_pasta
[2023-06-21 14:04:52,580] {task_command.py:370} INFO - Running <TaskInstance: dados_climaticos.criar_pasta scheduled__2023-05-29T00:00:00+00:00 [running]> on host alura
[2023-06-21 14:04:52,606] {taskinstance.py:1889} ERROR - Task failed with exception
Traceback (most recent call last):
  File "/home/gilmar/Documentos/airflowalura/venv/lib/python3.9/site-packages/airflow/models/taskinstance.py", line 1451, in _run_raw_task
    self._execute_task_with_callbacks(context, test_mode)
  File "/home/gilmar/Documentos/airflowalura/venv/lib/python3.9/site-packages/airflow/models/taskinstance.py", line 1555, in _execute_task_with_callbacks
    task_orig = self.render_templates(context=context)
  File "/home/gilmar/Documentos/airflowalura/venv/lib/python3.9/site-packages/airflow/models/taskinstance.py", line 2212, in render_templates
    rendered_task = self.task.render_template_fields(context)
  File "/home/gilmar/Documentos/airflowalura/venv/lib/python3.9/site-packages/airflow/models/baseoperator.py", line 1185, in render_template_fields
    self._do_render_template_fields(self, self.template_fields, context, jinja_env, set())
  File "/home/gilmar/Documentos/airflowalura/venv/lib/python3.9/site-packages/airflow/utils/session.py", line 71, in wrapper
    return func(*args, session=session, **kwargs)
  File "/home/gilmar/Documentos/airflowalura/venv/lib/python3.9/site-packages/airflow/models/abstractoperator.py", line 344, in _do_render_template_fields
    rendered_content = self.render_template(
  File "/home/gilmar/Documentos/airflowalura/venv/lib/python3.9/site-packages/airflow/models/abstractoperator.py", line 387, in render_template
    template = jinja_env.from_string(value)
  File "/home/gilmar/Documentos/airflowalura/venv/lib/python3.9/site-packages/jinja2/environment.py", line 1092, in from_string
    return cls.from_code(self, self.compile(source), gs, None)
  File "/home/gilmar/Documentos/airflowalura/venv/lib/python3.9/site-packages/jinja2/environment.py", line 757, in compile
    self.handle_exception(source=source_hint)
  File "/home/gilmar/Documentos/airflowalura/venv/lib/python3.9/site-packages/jinja2/environment.py", line 925, in handle_exception
    raise rewrite_traceback_stack(source=source)
  File "<unknown>", line 1, in template
jinja2.exceptions.TemplateSyntaxError: unexpected end of template, expected ','.
[2023-06-21 14:04:52,611] {taskinstance.py:1395} INFO - Marking task as FAILED. dag_id=dados_climaticos, task_id=criar_pasta, execution_date=20230529T000000, start_date=20230621T170452, end_date=20230621T170452
[2023-06-21 14:04:52,623] {standard_task_runner.py:92} ERROR - Failed to execute job 21 for task criar_pasta (unexpected end of template, expected ','.; 86783)
[2023-06-21 14:04:52,637] {local_task_job.py:156} INFO - Task exited with return code 1
[2023-06-21 14:04:52,663] {local_task_job.py:273} INFO - 0 downstream tasks scheduled from follow-on schedule check
[2023-06-21 14:08:56,120] {taskinstance.py:1159} INFO - Dependencies all met for <TaskInstance: dados_climaticos.criar_pasta scheduled__2023-05-29T00:00:00+00:00 [queued]>
[2023-06-21 14:08:56,124] {taskinstance.py:1159} INFO - Dependencies all met for <TaskInstance: dados_climaticos.criar_pasta scheduled__2023-05-29T00:00:00+00:00 [queued]>
[2023-06-21 14:08:56,124] {taskinstance.py:1356} INFO - 
--------------------------------------------------------------------------------
[2023-06-21 14:08:56,124] {taskinstance.py:1357} INFO - Starting attempt 1 of 1
[2023-06-21 14:08:56,125] {taskinstance.py:1358} INFO - 
--------------------------------------------------------------------------------
[2023-06-21 14:08:56,135] {taskinstance.py:1377} INFO - Executing <Task(BashOperator): criar_pasta> on 2023-05-29 00:00:00+00:00
[2023-06-21 14:08:56,138] {standard_task_runner.py:52} INFO - Started process 87065 to run task
[2023-06-21 14:08:56,142] {standard_task_runner.py:79} INFO - Running: ['airflow', 'tasks', 'run', 'dados_climaticos', 'criar_pasta', 'scheduled__2023-05-29T00:00:00+00:00', '--job-id', '21', '--raw', '--subdir', 'DAGS_FOLDER/dados_climaticos.py', '--cfg-path', '/tmp/tmp64x8dg3e', '--error-file', '/tmp/tmpujzhzq2_']
[2023-06-21 14:08:56,143] {standard_task_runner.py:80} INFO - Job 21: Subtask criar_pasta
[2023-06-21 14:08:56,180] {task_command.py:370} INFO - Running <TaskInstance: dados_climaticos.criar_pasta scheduled__2023-05-29T00:00:00+00:00 [running]> on host alura
[2023-06-21 14:08:56,202] {taskinstance.py:1889} ERROR - Task failed with exception
Traceback (most recent call last):
  File "/home/gilmar/Documentos/airflowalura/venv/lib/python3.9/site-packages/airflow/models/taskinstance.py", line 1451, in _run_raw_task
    self._execute_task_with_callbacks(context, test_mode)
  File "/home/gilmar/Documentos/airflowalura/venv/lib/python3.9/site-packages/airflow/models/taskinstance.py", line 1555, in _execute_task_with_callbacks
    task_orig = self.render_templates(context=context)
  File "/home/gilmar/Documentos/airflowalura/venv/lib/python3.9/site-packages/airflow/models/taskinstance.py", line 2212, in render_templates
    rendered_task = self.task.render_template_fields(context)
  File "/home/gilmar/Documentos/airflowalura/venv/lib/python3.9/site-packages/airflow/models/baseoperator.py", line 1185, in render_template_fields
    self._do_render_template_fields(self, self.template_fields, context, jinja_env, set())
  File "/home/gilmar/Documentos/airflowalura/venv/lib/python3.9/site-packages/airflow/utils/session.py", line 71, in wrapper
    return func(*args, session=session, **kwargs)
  File "/home/gilmar/Documentos/airflowalura/venv/lib/python3.9/site-packages/airflow/models/abstractoperator.py", line 344, in _do_render_template_fields
    rendered_content = self.render_template(
  File "/home/gilmar/Documentos/airflowalura/venv/lib/python3.9/site-packages/airflow/models/abstractoperator.py", line 387, in render_template
    template = jinja_env.from_string(value)
  File "/home/gilmar/Documentos/airflowalura/venv/lib/python3.9/site-packages/jinja2/environment.py", line 1092, in from_string
    return cls.from_code(self, self.compile(source), gs, None)
  File "/home/gilmar/Documentos/airflowalura/venv/lib/python3.9/site-packages/jinja2/environment.py", line 757, in compile
    self.handle_exception(source=source_hint)
  File "/home/gilmar/Documentos/airflowalura/venv/lib/python3.9/site-packages/jinja2/environment.py", line 925, in handle_exception
    raise rewrite_traceback_stack(source=source)
  File "<unknown>", line 1, in template
jinja2.exceptions.TemplateSyntaxError: unexpected end of template, expected ','.
[2023-06-21 14:08:56,208] {taskinstance.py:1395} INFO - Marking task as FAILED. dag_id=dados_climaticos, task_id=criar_pasta, execution_date=20230529T000000, start_date=20230621T170856, end_date=20230621T170856
[2023-06-21 14:08:56,217] {standard_task_runner.py:92} ERROR - Failed to execute job 21 for task criar_pasta (unexpected end of template, expected ','.; 87065)
[2023-06-21 14:08:56,236] {local_task_job.py:156} INFO - Task exited with return code 1
[2023-06-21 14:08:56,262] {local_task_job.py:273} INFO - 0 downstream tasks scheduled from follow-on schedule check
[2023-06-21 14:11:38,409] {taskinstance.py:1159} INFO - Dependencies all met for <TaskInstance: dados_climaticos.criar_pasta scheduled__2023-05-29T00:00:00+00:00 [queued]>
[2023-06-21 14:11:38,413] {taskinstance.py:1159} INFO - Dependencies all met for <TaskInstance: dados_climaticos.criar_pasta scheduled__2023-05-29T00:00:00+00:00 [queued]>
[2023-06-21 14:11:38,413] {taskinstance.py:1356} INFO - 
--------------------------------------------------------------------------------
[2023-06-21 14:11:38,413] {taskinstance.py:1357} INFO - Starting attempt 1 of 1
[2023-06-21 14:11:38,414] {taskinstance.py:1358} INFO - 
--------------------------------------------------------------------------------
[2023-06-21 14:11:38,427] {taskinstance.py:1377} INFO - Executing <Task(BashOperator): criar_pasta> on 2023-05-29 00:00:00+00:00
[2023-06-21 14:11:38,431] {standard_task_runner.py:52} INFO - Started process 87474 to run task
[2023-06-21 14:11:38,434] {standard_task_runner.py:79} INFO - Running: ['airflow', 'tasks', 'run', 'dados_climaticos', 'criar_pasta', 'scheduled__2023-05-29T00:00:00+00:00', '--job-id', '61', '--raw', '--subdir', 'DAGS_FOLDER/dados_climaticos.py', '--cfg-path', '/tmp/tmp6bjqc9ho', '--error-file', '/tmp/tmpjasic94i']
[2023-06-21 14:11:38,434] {standard_task_runner.py:80} INFO - Job 61: Subtask criar_pasta
[2023-06-21 14:11:38,472] {task_command.py:370} INFO - Running <TaskInstance: dados_climaticos.criar_pasta scheduled__2023-05-29T00:00:00+00:00 [running]> on host alura
[2023-06-21 14:11:38,492] {taskinstance.py:1889} ERROR - Task failed with exception
Traceback (most recent call last):
  File "/home/gilmar/Documentos/airflowalura/venv/lib/python3.9/site-packages/airflow/models/taskinstance.py", line 1451, in _run_raw_task
    self._execute_task_with_callbacks(context, test_mode)
  File "/home/gilmar/Documentos/airflowalura/venv/lib/python3.9/site-packages/airflow/models/taskinstance.py", line 1555, in _execute_task_with_callbacks
    task_orig = self.render_templates(context=context)
  File "/home/gilmar/Documentos/airflowalura/venv/lib/python3.9/site-packages/airflow/models/taskinstance.py", line 2212, in render_templates
    rendered_task = self.task.render_template_fields(context)
  File "/home/gilmar/Documentos/airflowalura/venv/lib/python3.9/site-packages/airflow/models/baseoperator.py", line 1185, in render_template_fields
    self._do_render_template_fields(self, self.template_fields, context, jinja_env, set())
  File "/home/gilmar/Documentos/airflowalura/venv/lib/python3.9/site-packages/airflow/utils/session.py", line 71, in wrapper
    return func(*args, session=session, **kwargs)
  File "/home/gilmar/Documentos/airflowalura/venv/lib/python3.9/site-packages/airflow/models/abstractoperator.py", line 344, in _do_render_template_fields
    rendered_content = self.render_template(
  File "/home/gilmar/Documentos/airflowalura/venv/lib/python3.9/site-packages/airflow/models/abstractoperator.py", line 387, in render_template
    template = jinja_env.from_string(value)
  File "/home/gilmar/Documentos/airflowalura/venv/lib/python3.9/site-packages/jinja2/environment.py", line 1092, in from_string
    return cls.from_code(self, self.compile(source), gs, None)
  File "/home/gilmar/Documentos/airflowalura/venv/lib/python3.9/site-packages/jinja2/environment.py", line 757, in compile
    self.handle_exception(source=source_hint)
  File "/home/gilmar/Documentos/airflowalura/venv/lib/python3.9/site-packages/jinja2/environment.py", line 925, in handle_exception
    raise rewrite_traceback_stack(source=source)
  File "<unknown>", line 1, in template
jinja2.exceptions.TemplateSyntaxError: unexpected end of template, expected ','.
[2023-06-21 14:11:38,495] {taskinstance.py:1395} INFO - Marking task as FAILED. dag_id=dados_climaticos, task_id=criar_pasta, execution_date=20230529T000000, start_date=20230621T171138, end_date=20230621T171138
[2023-06-21 14:11:38,504] {standard_task_runner.py:92} ERROR - Failed to execute job 61 for task criar_pasta (unexpected end of template, expected ','.; 87474)
[2023-06-21 14:11:38,529] {local_task_job.py:156} INFO - Task exited with return code 1
[2023-06-21 14:11:38,552] {local_task_job.py:273} INFO - 0 downstream tasks scheduled from follow-on schedule check
[2023-06-21 14:16:48,124] {taskinstance.py:1159} INFO - Dependencies all met for <TaskInstance: dados_climaticos.criar_pasta scheduled__2023-05-29T00:00:00+00:00 [queued]>
[2023-06-21 14:16:48,130] {taskinstance.py:1159} INFO - Dependencies all met for <TaskInstance: dados_climaticos.criar_pasta scheduled__2023-05-29T00:00:00+00:00 [queued]>
[2023-06-21 14:16:48,131] {taskinstance.py:1356} INFO - 
--------------------------------------------------------------------------------
[2023-06-21 14:16:48,131] {taskinstance.py:1357} INFO - Starting attempt 1 of 1
[2023-06-21 14:16:48,131] {taskinstance.py:1358} INFO - 
--------------------------------------------------------------------------------
[2023-06-21 14:16:48,147] {taskinstance.py:1377} INFO - Executing <Task(BashOperator): criar_pasta> on 2023-05-29 00:00:00+00:00
[2023-06-21 14:16:48,151] {standard_task_runner.py:52} INFO - Started process 87996 to run task
[2023-06-21 14:16:48,154] {standard_task_runner.py:79} INFO - Running: ['airflow', 'tasks', 'run', 'dados_climaticos', 'criar_pasta', 'scheduled__2023-05-29T00:00:00+00:00', '--job-id', '61', '--raw', '--subdir', 'DAGS_FOLDER/dados_climaticos.py', '--cfg-path', '/tmp/tmpyupqyio1', '--error-file', '/tmp/tmpqcmfqoul']
[2023-06-21 14:16:48,154] {standard_task_runner.py:80} INFO - Job 61: Subtask criar_pasta
[2023-06-21 14:16:48,195] {task_command.py:370} INFO - Running <TaskInstance: dados_climaticos.criar_pasta scheduled__2023-05-29T00:00:00+00:00 [running]> on host alura
[2023-06-21 14:16:48,217] {taskinstance.py:1889} ERROR - Task failed with exception
Traceback (most recent call last):
  File "/home/gilmar/Documentos/airflowalura/venv/lib/python3.9/site-packages/airflow/models/taskinstance.py", line 1451, in _run_raw_task
    self._execute_task_with_callbacks(context, test_mode)
  File "/home/gilmar/Documentos/airflowalura/venv/lib/python3.9/site-packages/airflow/models/taskinstance.py", line 1555, in _execute_task_with_callbacks
    task_orig = self.render_templates(context=context)
  File "/home/gilmar/Documentos/airflowalura/venv/lib/python3.9/site-packages/airflow/models/taskinstance.py", line 2212, in render_templates
    rendered_task = self.task.render_template_fields(context)
  File "/home/gilmar/Documentos/airflowalura/venv/lib/python3.9/site-packages/airflow/models/baseoperator.py", line 1185, in render_template_fields
    self._do_render_template_fields(self, self.template_fields, context, jinja_env, set())
  File "/home/gilmar/Documentos/airflowalura/venv/lib/python3.9/site-packages/airflow/utils/session.py", line 71, in wrapper
    return func(*args, session=session, **kwargs)
  File "/home/gilmar/Documentos/airflowalura/venv/lib/python3.9/site-packages/airflow/models/abstractoperator.py", line 344, in _do_render_template_fields
    rendered_content = self.render_template(
  File "/home/gilmar/Documentos/airflowalura/venv/lib/python3.9/site-packages/airflow/models/abstractoperator.py", line 387, in render_template
    template = jinja_env.from_string(value)
  File "/home/gilmar/Documentos/airflowalura/venv/lib/python3.9/site-packages/jinja2/environment.py", line 1092, in from_string
    return cls.from_code(self, self.compile(source), gs, None)
  File "/home/gilmar/Documentos/airflowalura/venv/lib/python3.9/site-packages/jinja2/environment.py", line 757, in compile
    self.handle_exception(source=source_hint)
  File "/home/gilmar/Documentos/airflowalura/venv/lib/python3.9/site-packages/jinja2/environment.py", line 925, in handle_exception
    raise rewrite_traceback_stack(source=source)
  File "<unknown>", line 1, in template
jinja2.exceptions.TemplateSyntaxError: unexpected end of template, expected ','.
[2023-06-21 14:16:48,221] {taskinstance.py:1395} INFO - Marking task as FAILED. dag_id=dados_climaticos, task_id=criar_pasta, execution_date=20230529T000000, start_date=20230621T171648, end_date=20230621T171648
[2023-06-21 14:16:48,230] {standard_task_runner.py:92} ERROR - Failed to execute job 61 for task criar_pasta (unexpected end of template, expected ','.; 87996)
[2023-06-21 14:16:48,249] {local_task_job.py:156} INFO - Task exited with return code 1
[2023-06-21 14:16:48,275] {local_task_job.py:273} INFO - 0 downstream tasks scheduled from follow-on schedule check
[2023-06-21 16:20:00,967] {taskinstance.py:1159} INFO - Dependencies all met for <TaskInstance: dados_climaticos.criar_pasta scheduled__2023-05-29T00:00:00+00:00 [queued]>
[2023-06-21 16:20:00,972] {taskinstance.py:1159} INFO - Dependencies all met for <TaskInstance: dados_climaticos.criar_pasta scheduled__2023-05-29T00:00:00+00:00 [queued]>
[2023-06-21 16:20:00,972] {taskinstance.py:1356} INFO - 
--------------------------------------------------------------------------------
[2023-06-21 16:20:00,972] {taskinstance.py:1357} INFO - Starting attempt 1 of 1
[2023-06-21 16:20:00,972] {taskinstance.py:1358} INFO - 
--------------------------------------------------------------------------------
[2023-06-21 16:20:00,981] {taskinstance.py:1377} INFO - Executing <Task(BashOperator): criar_pasta> on 2023-05-29 00:00:00+00:00
[2023-06-21 16:20:00,984] {standard_task_runner.py:52} INFO - Started process 6520 to run task
[2023-06-21 16:20:00,987] {standard_task_runner.py:79} INFO - Running: ['airflow', 'tasks', 'run', 'dados_climaticos', 'criar_pasta', 'scheduled__2023-05-29T00:00:00+00:00', '--job-id', '70', '--raw', '--subdir', 'DAGS_FOLDER/dados_climaticos.py', '--cfg-path', '/tmp/tmpq5jllph8', '--error-file', '/tmp/tmpjrmjlq_y']
[2023-06-21 16:20:00,988] {standard_task_runner.py:80} INFO - Job 70: Subtask criar_pasta
[2023-06-21 16:20:01,023] {task_command.py:370} INFO - Running <TaskInstance: dados_climaticos.criar_pasta scheduled__2023-05-29T00:00:00+00:00 [running]> on host alura
[2023-06-21 16:20:01,045] {taskinstance.py:1889} ERROR - Task failed with exception
Traceback (most recent call last):
  File "/home/gilmar/Documentos/airflowalura/venv/lib/python3.9/site-packages/airflow/models/taskinstance.py", line 1451, in _run_raw_task
    self._execute_task_with_callbacks(context, test_mode)
  File "/home/gilmar/Documentos/airflowalura/venv/lib/python3.9/site-packages/airflow/models/taskinstance.py", line 1555, in _execute_task_with_callbacks
    task_orig = self.render_templates(context=context)
  File "/home/gilmar/Documentos/airflowalura/venv/lib/python3.9/site-packages/airflow/models/taskinstance.py", line 2212, in render_templates
    rendered_task = self.task.render_template_fields(context)
  File "/home/gilmar/Documentos/airflowalura/venv/lib/python3.9/site-packages/airflow/models/baseoperator.py", line 1185, in render_template_fields
    self._do_render_template_fields(self, self.template_fields, context, jinja_env, set())
  File "/home/gilmar/Documentos/airflowalura/venv/lib/python3.9/site-packages/airflow/utils/session.py", line 71, in wrapper
    return func(*args, session=session, **kwargs)
  File "/home/gilmar/Documentos/airflowalura/venv/lib/python3.9/site-packages/airflow/models/abstractoperator.py", line 344, in _do_render_template_fields
    rendered_content = self.render_template(
  File "/home/gilmar/Documentos/airflowalura/venv/lib/python3.9/site-packages/airflow/models/abstractoperator.py", line 387, in render_template
    template = jinja_env.from_string(value)
  File "/home/gilmar/Documentos/airflowalura/venv/lib/python3.9/site-packages/jinja2/environment.py", line 1092, in from_string
    return cls.from_code(self, self.compile(source), gs, None)
  File "/home/gilmar/Documentos/airflowalura/venv/lib/python3.9/site-packages/jinja2/environment.py", line 757, in compile
    self.handle_exception(source=source_hint)
  File "/home/gilmar/Documentos/airflowalura/venv/lib/python3.9/site-packages/jinja2/environment.py", line 925, in handle_exception
    raise rewrite_traceback_stack(source=source)
  File "<unknown>", line 1, in template
jinja2.exceptions.TemplateSyntaxError: unexpected end of template, expected ','.
[2023-06-21 16:20:01,050] {taskinstance.py:1395} INFO - Marking task as FAILED. dag_id=dados_climaticos, task_id=criar_pasta, execution_date=20230529T000000, start_date=20230621T192000, end_date=20230621T192001
[2023-06-21 16:20:01,058] {standard_task_runner.py:92} ERROR - Failed to execute job 70 for task criar_pasta (unexpected end of template, expected ','.; 6520)
[2023-06-21 16:20:01,084] {local_task_job.py:156} INFO - Task exited with return code 1
[2023-06-21 16:20:01,113] {local_task_job.py:273} INFO - 0 downstream tasks scheduled from follow-on schedule check
