[2023-06-21 16:36:16,534] {taskinstance.py:1159} INFO - Dependencies all met for <TaskInstance: dados_climaticos.extrai_dados scheduled__2023-04-24T00:00:00+00:00 [queued]>
[2023-06-21 16:36:16,538] {taskinstance.py:1159} INFO - Dependencies all met for <TaskInstance: dados_climaticos.extrai_dados scheduled__2023-04-24T00:00:00+00:00 [queued]>
[2023-06-21 16:36:16,538] {taskinstance.py:1356} INFO - 
--------------------------------------------------------------------------------
[2023-06-21 16:36:16,538] {taskinstance.py:1357} INFO - Starting attempt 1 of 1
[2023-06-21 16:36:16,538] {taskinstance.py:1358} INFO - 
--------------------------------------------------------------------------------
[2023-06-21 16:36:16,549] {taskinstance.py:1377} INFO - Executing <Task(PythonOperator): extrai_dados> on 2023-04-24 00:00:00+00:00
[2023-06-21 16:36:16,553] {standard_task_runner.py:52} INFO - Started process 12087 to run task
[2023-06-21 16:36:16,555] {standard_task_runner.py:79} INFO - Running: ['airflow', 'tasks', 'run', 'dados_climaticos', 'extrai_dados', 'scheduled__2023-04-24T00:00:00+00:00', '--job-id', '125', '--raw', '--subdir', 'DAGS_FOLDER/dados_climaticos.py', '--cfg-path', '/tmp/tmpnx7beu6w', '--error-file', '/tmp/tmpiyxi7ygu']
[2023-06-21 16:36:16,556] {standard_task_runner.py:80} INFO - Job 125: Subtask extrai_dados
[2023-06-21 16:36:16,586] {task_command.py:370} INFO - Running <TaskInstance: dados_climaticos.extrai_dados scheduled__2023-04-24T00:00:00+00:00 [running]> on host alura
[2023-06-21 16:36:16,618] {taskinstance.py:1569} INFO - Exporting the following env vars:
AIRFLOW_CTX_DAG_OWNER=airflow
AIRFLOW_CTX_DAG_ID=dados_climaticos
AIRFLOW_CTX_TASK_ID=extrai_dados
AIRFLOW_CTX_EXECUTION_DATE=2023-04-24T00:00:00+00:00
AIRFLOW_CTX_TRY_NUMBER=1
AIRFLOW_CTX_DAG_RUN_ID=scheduled__2023-04-24T00:00:00+00:00
[2023-06-21 16:36:17,196] {taskinstance.py:1889} ERROR - Task failed with exception
Traceback (most recent call last):
  File "/home/gilmar/Documentos/airflowalura/venv/lib/python3.9/site-packages/airflow/operators/python.py", line 171, in execute
    return_value = self.execute_callable()
  File "/home/gilmar/Documentos/airflowalura/venv/lib/python3.9/site-packages/airflow/operators/python.py", line 189, in execute_callable
    return self.python_callable(*self.op_args, **self.op_kwargs)
  File "/home/gilmar/Documentos/airflowalura/dags/dados_climaticos.py", line 27, in extrai_dados
    dados = pd.read_csv(URL)
  File "/home/gilmar/Documentos/airflowalura/venv/lib/python3.9/site-packages/pandas/io/parsers/readers.py", line 912, in read_csv
    return _read(filepath_or_buffer, kwds)
  File "/home/gilmar/Documentos/airflowalura/venv/lib/python3.9/site-packages/pandas/io/parsers/readers.py", line 577, in _read
    parser = TextFileReader(filepath_or_buffer, **kwds)
  File "/home/gilmar/Documentos/airflowalura/venv/lib/python3.9/site-packages/pandas/io/parsers/readers.py", line 1407, in __init__
    self._engine = self._make_engine(f, self.engine)
  File "/home/gilmar/Documentos/airflowalura/venv/lib/python3.9/site-packages/pandas/io/parsers/readers.py", line 1661, in _make_engine
    self.handles = get_handle(
  File "/home/gilmar/Documentos/airflowalura/venv/lib/python3.9/site-packages/pandas/io/common.py", line 716, in get_handle
    ioargs = _get_filepath_or_buffer(
  File "/home/gilmar/Documentos/airflowalura/venv/lib/python3.9/site-packages/pandas/io/common.py", line 368, in _get_filepath_or_buffer
    with urlopen(req_info) as req:
  File "/home/gilmar/Documentos/airflowalura/venv/lib/python3.9/site-packages/pandas/io/common.py", line 270, in urlopen
    return urllib.request.urlopen(*args, **kwargs)
  File "/usr/lib/python3.9/urllib/request.py", line 214, in urlopen
    return opener.open(url, data, timeout)
  File "/usr/lib/python3.9/urllib/request.py", line 523, in open
    response = meth(req, response)
  File "/usr/lib/python3.9/urllib/request.py", line 632, in http_response
    response = self.parent.error(
  File "/usr/lib/python3.9/urllib/request.py", line 561, in error
    return self._call_chain(*args)
  File "/usr/lib/python3.9/urllib/request.py", line 494, in _call_chain
    result = func(*args)
  File "/usr/lib/python3.9/urllib/request.py", line 641, in http_error_default
    raise HTTPError(req.full_url, code, msg, hdrs, fp)
urllib.error.HTTPError: HTTP Error 401: 
[2023-06-21 16:36:17,200] {taskinstance.py:1395} INFO - Marking task as FAILED. dag_id=dados_climaticos, task_id=extrai_dados, execution_date=20230424T000000, start_date=20230621T193616, end_date=20230621T193617
[2023-06-21 16:36:17,210] {standard_task_runner.py:92} ERROR - Failed to execute job 125 for task extrai_dados (HTTP Error 401: ; 12087)
[2023-06-21 16:36:17,221] {local_task_job.py:156} INFO - Task exited with return code 1
[2023-06-21 16:36:17,233] {local_task_job.py:273} INFO - 0 downstream tasks scheduled from follow-on schedule check
