[2023-06-21 16:31:16,744] {taskinstance.py:1159} INFO - Dependencies all met for <TaskInstance: dados_climaticos.extrai_dados scheduled__2023-05-29T00:00:00+00:00 [queued]>
[2023-06-21 16:31:16,748] {taskinstance.py:1159} INFO - Dependencies all met for <TaskInstance: dados_climaticos.extrai_dados scheduled__2023-05-29T00:00:00+00:00 [queued]>
[2023-06-21 16:31:16,748] {taskinstance.py:1356} INFO - 
--------------------------------------------------------------------------------
[2023-06-21 16:31:16,749] {taskinstance.py:1357} INFO - Starting attempt 1 of 1
[2023-06-21 16:31:16,749] {taskinstance.py:1358} INFO - 
--------------------------------------------------------------------------------
[2023-06-21 16:31:16,769] {taskinstance.py:1377} INFO - Executing <Task(PythonOperator): extrai_dados> on 2023-05-29 00:00:00+00:00
[2023-06-21 16:31:16,772] {standard_task_runner.py:52} INFO - Started process 10282 to run task
[2023-06-21 16:31:16,775] {standard_task_runner.py:79} INFO - Running: ['airflow', 'tasks', 'run', 'dados_climaticos', 'extrai_dados', 'scheduled__2023-05-29T00:00:00+00:00', '--job-id', '83', '--raw', '--subdir', 'DAGS_FOLDER/dados_climaticos.py', '--cfg-path', '/tmp/tmp4uhlcz84', '--error-file', '/tmp/tmpvylm8v83']
[2023-06-21 16:31:16,776] {standard_task_runner.py:80} INFO - Job 83: Subtask extrai_dados
[2023-06-21 16:31:16,809] {task_command.py:370} INFO - Running <TaskInstance: dados_climaticos.extrai_dados scheduled__2023-05-29T00:00:00+00:00 [running]> on host alura
[2023-06-21 16:31:16,845] {taskinstance.py:1569} INFO - Exporting the following env vars:
AIRFLOW_CTX_DAG_OWNER=airflow
AIRFLOW_CTX_DAG_ID=dados_climaticos
AIRFLOW_CTX_TASK_ID=extrai_dados
AIRFLOW_CTX_EXECUTION_DATE=2023-05-29T00:00:00+00:00
AIRFLOW_CTX_TRY_NUMBER=1
AIRFLOW_CTX_DAG_RUN_ID=scheduled__2023-05-29T00:00:00+00:00
[2023-06-21 16:31:17,606] {taskinstance.py:1889} ERROR - Task failed with exception
Traceback (most recent call last):
  File "/home/gilmar/Documentos/airflowalura/venv/lib/python3.9/site-packages/airflow/operators/python.py", line 171, in execute
    return_value = self.execute_callable()
  File "/home/gilmar/Documentos/airflowalura/venv/lib/python3.9/site-packages/airflow/operators/python.py", line 189, in execute_callable
    return self.python_callable(*self.op_args, **self.op_kwargs)
  File "/home/gilmar/Documentos/airflowalura/dags/dados_climaticos.py", line 31, in extrai_dados
    dados.to_csv(file_path + 'dados_brutos.csv')
  File "/home/gilmar/Documentos/airflowalura/venv/lib/python3.9/site-packages/pandas/core/generic.py", line 3772, in to_csv
    return DataFrameRenderer(formatter).to_csv(
  File "/home/gilmar/Documentos/airflowalura/venv/lib/python3.9/site-packages/pandas/io/formats/format.py", line 1186, in to_csv
    csv_formatter.save()
  File "/home/gilmar/Documentos/airflowalura/venv/lib/python3.9/site-packages/pandas/io/formats/csvs.py", line 240, in save
    with get_handle(
  File "/home/gilmar/Documentos/airflowalura/venv/lib/python3.9/site-packages/pandas/io/common.py", line 737, in get_handle
    check_parent_directory(str(handle))
  File "/home/gilmar/Documentos/airflowalura/venv/lib/python3.9/site-packages/pandas/io/common.py", line 600, in check_parent_directory
    raise OSError(rf"Cannot save file into a non-existent directory: '{parent}'")
OSError: Cannot save file into a non-existent directory: 'home/millenagena/Documents/airflowalura/semana=2023-06-05'
[2023-06-21 16:31:17,617] {taskinstance.py:1395} INFO - Marking task as FAILED. dag_id=dados_climaticos, task_id=extrai_dados, execution_date=20230529T000000, start_date=20230621T193116, end_date=20230621T193117
[2023-06-21 16:31:17,627] {standard_task_runner.py:92} ERROR - Failed to execute job 83 for task extrai_dados (Cannot save file into a non-existent directory: 'home/millenagena/Documents/airflowalura/semana=2023-06-05'; 10282)
[2023-06-21 16:31:17,641] {local_task_job.py:156} INFO - Task exited with return code 1
[2023-06-21 16:31:17,656] {local_task_job.py:273} INFO - 0 downstream tasks scheduled from follow-on schedule check
[2023-06-22 10:18:41,186] {taskinstance.py:1159} INFO - Dependencies all met for <TaskInstance: dados_climaticos.extrai_dados scheduled__2023-05-29T00:00:00+00:00 [queued]>
[2023-06-22 10:18:41,191] {taskinstance.py:1159} INFO - Dependencies all met for <TaskInstance: dados_climaticos.extrai_dados scheduled__2023-05-29T00:00:00+00:00 [queued]>
[2023-06-22 10:18:41,191] {taskinstance.py:1356} INFO - 
--------------------------------------------------------------------------------
[2023-06-22 10:18:41,192] {taskinstance.py:1357} INFO - Starting attempt 1 of 1
[2023-06-22 10:18:41,192] {taskinstance.py:1358} INFO - 
--------------------------------------------------------------------------------
[2023-06-22 10:18:41,204] {taskinstance.py:1377} INFO - Executing <Task(PythonOperator): extrai_dados> on 2023-05-29 00:00:00+00:00
[2023-06-22 10:18:41,208] {standard_task_runner.py:52} INFO - Started process 8917 to run task
[2023-06-22 10:18:41,211] {standard_task_runner.py:79} INFO - Running: ['airflow', 'tasks', 'run', 'dados_climaticos', 'extrai_dados', 'scheduled__2023-05-29T00:00:00+00:00', '--job-id', '149', '--raw', '--subdir', 'DAGS_FOLDER/dados_climaticos.py', '--cfg-path', '/tmp/tmpioki5nwe', '--error-file', '/tmp/tmp8ni95lts']
[2023-06-22 10:18:41,211] {standard_task_runner.py:80} INFO - Job 149: Subtask extrai_dados
[2023-06-22 10:18:41,244] {task_command.py:370} INFO - Running <TaskInstance: dados_climaticos.extrai_dados scheduled__2023-05-29T00:00:00+00:00 [running]> on host alura
[2023-06-22 10:18:41,286] {taskinstance.py:1569} INFO - Exporting the following env vars:
AIRFLOW_CTX_DAG_OWNER=airflow
AIRFLOW_CTX_DAG_ID=dados_climaticos
AIRFLOW_CTX_TASK_ID=extrai_dados
AIRFLOW_CTX_EXECUTION_DATE=2023-05-29T00:00:00+00:00
AIRFLOW_CTX_TRY_NUMBER=1
AIRFLOW_CTX_DAG_RUN_ID=scheduled__2023-05-29T00:00:00+00:00
[2023-06-22 10:18:41,971] {python.py:173} INFO - Done. Returned value was: None
[2023-06-22 10:18:41,976] {taskinstance.py:1395} INFO - Marking task as SUCCESS. dag_id=dados_climaticos, task_id=extrai_dados, execution_date=20230529T000000, start_date=20230622T131841, end_date=20230622T131841
[2023-06-22 10:18:41,997] {local_task_job.py:156} INFO - Task exited with return code 0
[2023-06-22 10:18:42,013] {local_task_job.py:273} INFO - 0 downstream tasks scheduled from follow-on schedule check
