[2023-06-21 13:52:20,026] {taskinstance.py:1159} INFO - Dependencies all met for <TaskInstance: dados_climaticos.criar_pasta scheduled__2023-06-05T00:00:00+00:00 [queued]>
[2023-06-21 13:52:20,030] {taskinstance.py:1159} INFO - Dependencies all met for <TaskInstance: dados_climaticos.criar_pasta scheduled__2023-06-05T00:00:00+00:00 [queued]>
[2023-06-21 13:52:20,030] {taskinstance.py:1356} INFO - 
--------------------------------------------------------------------------------
[2023-06-21 13:52:20,031] {taskinstance.py:1357} INFO - Starting attempt 1 of 1
[2023-06-21 13:52:20,031] {taskinstance.py:1358} INFO - 
--------------------------------------------------------------------------------
[2023-06-21 13:52:20,046] {taskinstance.py:1377} INFO - Executing <Task(BashOperator): criar_pasta> on 2023-06-05 00:00:00+00:00
[2023-06-21 13:52:20,049] {standard_task_runner.py:52} INFO - Started process 85545 to run task
[2023-06-21 13:52:20,052] {standard_task_runner.py:79} INFO - Running: ['airflow', 'tasks', 'run', 'dados_climaticos', 'criar_pasta', 'scheduled__2023-06-05T00:00:00+00:00', '--job-id', '15', '--raw', '--subdir', 'DAGS_FOLDER/dados_climaticos.py', '--cfg-path', '/tmp/tmpw218gq9z', '--error-file', '/tmp/tmpy_nponzv']
[2023-06-21 13:52:20,053] {standard_task_runner.py:80} INFO - Job 15: Subtask criar_pasta
[2023-06-21 13:52:20,102] {task_command.py:370} INFO - Running <TaskInstance: dados_climaticos.criar_pasta scheduled__2023-06-05T00:00:00+00:00 [running]> on host alura
[2023-06-21 13:52:20,128] {taskinstance.py:1889} ERROR - Task failed with exception
Traceback (most recent call last):
  File "/home/gilmar/Documentos/airflowalura/venv/lib/python3.9/site-packages/airflow/models/taskinstance.py", line 1451, in _run_raw_task
    self._execute_task_with_callbacks(context, test_mode)
  File "/home/gilmar/Documentos/airflowalura/venv/lib/python3.9/site-packages/airflow/models/taskinstance.py", line 1555, in _execute_task_with_callbacks
    task_orig = self.render_templates(context=context)
  File "/home/gilmar/Documentos/airflowalura/venv/lib/python3.9/site-packages/airflow/models/taskinstance.py", line 2212, in render_templates
    rendered_task = self.task.render_template_fields(context)
  File "/home/gilmar/Documentos/airflowalura/venv/lib/python3.9/site-packages/airflow/models/baseoperator.py", line 1185, in render_template_fields
    self._do_render_template_fields(self, self.template_fields, context, jinja_env, set())
  File "/home/gilmar/Documentos/airflowalura/venv/lib/python3.9/site-packages/airflow/utils/session.py", line 71, in wrapper
    return func(*args, session=session, **kwargs)
  File "/home/gilmar/Documentos/airflowalura/venv/lib/python3.9/site-packages/airflow/models/abstractoperator.py", line 344, in _do_render_template_fields
    rendered_content = self.render_template(
  File "/home/gilmar/Documentos/airflowalura/venv/lib/python3.9/site-packages/airflow/models/abstractoperator.py", line 387, in render_template
    template = jinja_env.from_string(value)
  File "/home/gilmar/Documentos/airflowalura/venv/lib/python3.9/site-packages/jinja2/environment.py", line 1092, in from_string
    return cls.from_code(self, self.compile(source), gs, None)
  File "/home/gilmar/Documentos/airflowalura/venv/lib/python3.9/site-packages/jinja2/environment.py", line 757, in compile
    self.handle_exception(source=source_hint)
  File "/home/gilmar/Documentos/airflowalura/venv/lib/python3.9/site-packages/jinja2/environment.py", line 925, in handle_exception
    raise rewrite_traceback_stack(source=source)
  File "<unknown>", line 1, in template
jinja2.exceptions.TemplateSyntaxError: unexpected end of template, expected ','.
[2023-06-21 13:52:20,135] {taskinstance.py:1395} INFO - Marking task as FAILED. dag_id=dados_climaticos, task_id=criar_pasta, execution_date=20230605T000000, start_date=20230621T165220, end_date=20230621T165220
[2023-06-21 13:52:20,147] {standard_task_runner.py:92} ERROR - Failed to execute job 15 for task criar_pasta (unexpected end of template, expected ','.; 85545)
[2023-06-21 13:52:20,191] {local_task_job.py:156} INFO - Task exited with return code 1
[2023-06-21 13:52:20,239] {local_task_job.py:273} INFO - 0 downstream tasks scheduled from follow-on schedule check
[2023-06-21 14:04:54,248] {taskinstance.py:1159} INFO - Dependencies all met for <TaskInstance: dados_climaticos.criar_pasta scheduled__2023-06-05T00:00:00+00:00 [queued]>
[2023-06-21 14:04:54,254] {taskinstance.py:1159} INFO - Dependencies all met for <TaskInstance: dados_climaticos.criar_pasta scheduled__2023-06-05T00:00:00+00:00 [queued]>
[2023-06-21 14:04:54,254] {taskinstance.py:1356} INFO - 
--------------------------------------------------------------------------------
[2023-06-21 14:04:54,254] {taskinstance.py:1357} INFO - Starting attempt 1 of 1
[2023-06-21 14:04:54,254] {taskinstance.py:1358} INFO - 
--------------------------------------------------------------------------------
[2023-06-21 14:04:54,264] {taskinstance.py:1377} INFO - Executing <Task(BashOperator): criar_pasta> on 2023-06-05 00:00:00+00:00
[2023-06-21 14:04:54,267] {standard_task_runner.py:52} INFO - Started process 86789 to run task
[2023-06-21 14:04:54,271] {standard_task_runner.py:79} INFO - Running: ['airflow', 'tasks', 'run', 'dados_climaticos', 'criar_pasta', 'scheduled__2023-06-05T00:00:00+00:00', '--job-id', '22', '--raw', '--subdir', 'DAGS_FOLDER/dados_climaticos.py', '--cfg-path', '/tmp/tmp69_agkan', '--error-file', '/tmp/tmpztfbm8dg']
[2023-06-21 14:04:54,271] {standard_task_runner.py:80} INFO - Job 22: Subtask criar_pasta
[2023-06-21 14:04:54,307] {task_command.py:370} INFO - Running <TaskInstance: dados_climaticos.criar_pasta scheduled__2023-06-05T00:00:00+00:00 [running]> on host alura
[2023-06-21 14:04:54,327] {taskinstance.py:1889} ERROR - Task failed with exception
Traceback (most recent call last):
  File "/home/gilmar/Documentos/airflowalura/venv/lib/python3.9/site-packages/airflow/models/taskinstance.py", line 1451, in _run_raw_task
    self._execute_task_with_callbacks(context, test_mode)
  File "/home/gilmar/Documentos/airflowalura/venv/lib/python3.9/site-packages/airflow/models/taskinstance.py", line 1555, in _execute_task_with_callbacks
    task_orig = self.render_templates(context=context)
  File "/home/gilmar/Documentos/airflowalura/venv/lib/python3.9/site-packages/airflow/models/taskinstance.py", line 2212, in render_templates
    rendered_task = self.task.render_template_fields(context)
  File "/home/gilmar/Documentos/airflowalura/venv/lib/python3.9/site-packages/airflow/models/baseoperator.py", line 1185, in render_template_fields
    self._do_render_template_fields(self, self.template_fields, context, jinja_env, set())
  File "/home/gilmar/Documentos/airflowalura/venv/lib/python3.9/site-packages/airflow/utils/session.py", line 71, in wrapper
    return func(*args, session=session, **kwargs)
  File "/home/gilmar/Documentos/airflowalura/venv/lib/python3.9/site-packages/airflow/models/abstractoperator.py", line 344, in _do_render_template_fields
    rendered_content = self.render_template(
  File "/home/gilmar/Documentos/airflowalura/venv/lib/python3.9/site-packages/airflow/models/abstractoperator.py", line 387, in render_template
    template = jinja_env.from_string(value)
  File "/home/gilmar/Documentos/airflowalura/venv/lib/python3.9/site-packages/jinja2/environment.py", line 1092, in from_string
    return cls.from_code(self, self.compile(source), gs, None)
  File "/home/gilmar/Documentos/airflowalura/venv/lib/python3.9/site-packages/jinja2/environment.py", line 757, in compile
    self.handle_exception(source=source_hint)
  File "/home/gilmar/Documentos/airflowalura/venv/lib/python3.9/site-packages/jinja2/environment.py", line 925, in handle_exception
    raise rewrite_traceback_stack(source=source)
  File "<unknown>", line 1, in template
jinja2.exceptions.TemplateSyntaxError: unexpected end of template, expected ','.
[2023-06-21 14:04:54,332] {taskinstance.py:1395} INFO - Marking task as FAILED. dag_id=dados_climaticos, task_id=criar_pasta, execution_date=20230605T000000, start_date=20230621T170454, end_date=20230621T170454
[2023-06-21 14:04:54,345] {standard_task_runner.py:92} ERROR - Failed to execute job 22 for task criar_pasta (unexpected end of template, expected ','.; 86789)
[2023-06-21 14:04:54,365] {local_task_job.py:156} INFO - Task exited with return code 1
[2023-06-21 14:04:54,390] {local_task_job.py:273} INFO - 0 downstream tasks scheduled from follow-on schedule check
[2023-06-21 14:08:57,881] {taskinstance.py:1159} INFO - Dependencies all met for <TaskInstance: dados_climaticos.criar_pasta scheduled__2023-06-05T00:00:00+00:00 [queued]>
[2023-06-21 14:08:57,887] {taskinstance.py:1159} INFO - Dependencies all met for <TaskInstance: dados_climaticos.criar_pasta scheduled__2023-06-05T00:00:00+00:00 [queued]>
[2023-06-21 14:08:57,887] {taskinstance.py:1356} INFO - 
--------------------------------------------------------------------------------
[2023-06-21 14:08:57,887] {taskinstance.py:1357} INFO - Starting attempt 1 of 1
[2023-06-21 14:08:57,887] {taskinstance.py:1358} INFO - 
--------------------------------------------------------------------------------
[2023-06-21 14:08:57,897] {taskinstance.py:1377} INFO - Executing <Task(BashOperator): criar_pasta> on 2023-06-05 00:00:00+00:00
[2023-06-21 14:08:57,900] {standard_task_runner.py:52} INFO - Started process 87071 to run task
[2023-06-21 14:08:57,903] {standard_task_runner.py:79} INFO - Running: ['airflow', 'tasks', 'run', 'dados_climaticos', 'criar_pasta', 'scheduled__2023-06-05T00:00:00+00:00', '--job-id', '22', '--raw', '--subdir', 'DAGS_FOLDER/dados_climaticos.py', '--cfg-path', '/tmp/tmplr5_y1ze', '--error-file', '/tmp/tmp416_y59i']
[2023-06-21 14:08:57,904] {standard_task_runner.py:80} INFO - Job 22: Subtask criar_pasta
[2023-06-21 14:08:57,944] {task_command.py:370} INFO - Running <TaskInstance: dados_climaticos.criar_pasta scheduled__2023-06-05T00:00:00+00:00 [running]> on host alura
[2023-06-21 14:08:57,964] {taskinstance.py:1889} ERROR - Task failed with exception
Traceback (most recent call last):
  File "/home/gilmar/Documentos/airflowalura/venv/lib/python3.9/site-packages/airflow/models/taskinstance.py", line 1451, in _run_raw_task
    self._execute_task_with_callbacks(context, test_mode)
  File "/home/gilmar/Documentos/airflowalura/venv/lib/python3.9/site-packages/airflow/models/taskinstance.py", line 1555, in _execute_task_with_callbacks
    task_orig = self.render_templates(context=context)
  File "/home/gilmar/Documentos/airflowalura/venv/lib/python3.9/site-packages/airflow/models/taskinstance.py", line 2212, in render_templates
    rendered_task = self.task.render_template_fields(context)
  File "/home/gilmar/Documentos/airflowalura/venv/lib/python3.9/site-packages/airflow/models/baseoperator.py", line 1185, in render_template_fields
    self._do_render_template_fields(self, self.template_fields, context, jinja_env, set())
  File "/home/gilmar/Documentos/airflowalura/venv/lib/python3.9/site-packages/airflow/utils/session.py", line 71, in wrapper
    return func(*args, session=session, **kwargs)
  File "/home/gilmar/Documentos/airflowalura/venv/lib/python3.9/site-packages/airflow/models/abstractoperator.py", line 344, in _do_render_template_fields
    rendered_content = self.render_template(
  File "/home/gilmar/Documentos/airflowalura/venv/lib/python3.9/site-packages/airflow/models/abstractoperator.py", line 387, in render_template
    template = jinja_env.from_string(value)
  File "/home/gilmar/Documentos/airflowalura/venv/lib/python3.9/site-packages/jinja2/environment.py", line 1092, in from_string
    return cls.from_code(self, self.compile(source), gs, None)
  File "/home/gilmar/Documentos/airflowalura/venv/lib/python3.9/site-packages/jinja2/environment.py", line 757, in compile
    self.handle_exception(source=source_hint)
  File "/home/gilmar/Documentos/airflowalura/venv/lib/python3.9/site-packages/jinja2/environment.py", line 925, in handle_exception
    raise rewrite_traceback_stack(source=source)
  File "<unknown>", line 1, in template
jinja2.exceptions.TemplateSyntaxError: unexpected end of template, expected ','.
[2023-06-21 14:08:57,969] {taskinstance.py:1395} INFO - Marking task as FAILED. dag_id=dados_climaticos, task_id=criar_pasta, execution_date=20230605T000000, start_date=20230621T170857, end_date=20230621T170857
[2023-06-21 14:08:57,978] {standard_task_runner.py:92} ERROR - Failed to execute job 22 for task criar_pasta (unexpected end of template, expected ','.; 87071)
[2023-06-21 14:08:57,999] {local_task_job.py:156} INFO - Task exited with return code 1
[2023-06-21 14:08:58,029] {local_task_job.py:273} INFO - 0 downstream tasks scheduled from follow-on schedule check
[2023-06-21 14:11:40,102] {taskinstance.py:1159} INFO - Dependencies all met for <TaskInstance: dados_climaticos.criar_pasta scheduled__2023-06-05T00:00:00+00:00 [queued]>
[2023-06-21 14:11:40,107] {taskinstance.py:1159} INFO - Dependencies all met for <TaskInstance: dados_climaticos.criar_pasta scheduled__2023-06-05T00:00:00+00:00 [queued]>
[2023-06-21 14:11:40,108] {taskinstance.py:1356} INFO - 
--------------------------------------------------------------------------------
[2023-06-21 14:11:40,108] {taskinstance.py:1357} INFO - Starting attempt 1 of 1
[2023-06-21 14:11:40,108] {taskinstance.py:1358} INFO - 
--------------------------------------------------------------------------------
[2023-06-21 14:11:40,120] {taskinstance.py:1377} INFO - Executing <Task(BashOperator): criar_pasta> on 2023-06-05 00:00:00+00:00
[2023-06-21 14:11:40,124] {standard_task_runner.py:52} INFO - Started process 87480 to run task
[2023-06-21 14:11:40,127] {standard_task_runner.py:79} INFO - Running: ['airflow', 'tasks', 'run', 'dados_climaticos', 'criar_pasta', 'scheduled__2023-06-05T00:00:00+00:00', '--job-id', '62', '--raw', '--subdir', 'DAGS_FOLDER/dados_climaticos.py', '--cfg-path', '/tmp/tmp8fgt73cz', '--error-file', '/tmp/tmpsysndf_a']
[2023-06-21 14:11:40,128] {standard_task_runner.py:80} INFO - Job 62: Subtask criar_pasta
[2023-06-21 14:11:40,161] {task_command.py:370} INFO - Running <TaskInstance: dados_climaticos.criar_pasta scheduled__2023-06-05T00:00:00+00:00 [running]> on host alura
[2023-06-21 14:11:40,184] {taskinstance.py:1889} ERROR - Task failed with exception
Traceback (most recent call last):
  File "/home/gilmar/Documentos/airflowalura/venv/lib/python3.9/site-packages/airflow/models/taskinstance.py", line 1451, in _run_raw_task
    self._execute_task_with_callbacks(context, test_mode)
  File "/home/gilmar/Documentos/airflowalura/venv/lib/python3.9/site-packages/airflow/models/taskinstance.py", line 1555, in _execute_task_with_callbacks
    task_orig = self.render_templates(context=context)
  File "/home/gilmar/Documentos/airflowalura/venv/lib/python3.9/site-packages/airflow/models/taskinstance.py", line 2212, in render_templates
    rendered_task = self.task.render_template_fields(context)
  File "/home/gilmar/Documentos/airflowalura/venv/lib/python3.9/site-packages/airflow/models/baseoperator.py", line 1185, in render_template_fields
    self._do_render_template_fields(self, self.template_fields, context, jinja_env, set())
  File "/home/gilmar/Documentos/airflowalura/venv/lib/python3.9/site-packages/airflow/utils/session.py", line 71, in wrapper
    return func(*args, session=session, **kwargs)
  File "/home/gilmar/Documentos/airflowalura/venv/lib/python3.9/site-packages/airflow/models/abstractoperator.py", line 344, in _do_render_template_fields
    rendered_content = self.render_template(
  File "/home/gilmar/Documentos/airflowalura/venv/lib/python3.9/site-packages/airflow/models/abstractoperator.py", line 387, in render_template
    template = jinja_env.from_string(value)
  File "/home/gilmar/Documentos/airflowalura/venv/lib/python3.9/site-packages/jinja2/environment.py", line 1092, in from_string
    return cls.from_code(self, self.compile(source), gs, None)
  File "/home/gilmar/Documentos/airflowalura/venv/lib/python3.9/site-packages/jinja2/environment.py", line 757, in compile
    self.handle_exception(source=source_hint)
  File "/home/gilmar/Documentos/airflowalura/venv/lib/python3.9/site-packages/jinja2/environment.py", line 925, in handle_exception
    raise rewrite_traceback_stack(source=source)
  File "<unknown>", line 1, in template
jinja2.exceptions.TemplateSyntaxError: unexpected end of template, expected ','.
[2023-06-21 14:11:40,189] {taskinstance.py:1395} INFO - Marking task as FAILED. dag_id=dados_climaticos, task_id=criar_pasta, execution_date=20230605T000000, start_date=20230621T171140, end_date=20230621T171140
[2023-06-21 14:11:40,200] {standard_task_runner.py:92} ERROR - Failed to execute job 62 for task criar_pasta (unexpected end of template, expected ','.; 87480)
[2023-06-21 14:11:40,223] {local_task_job.py:156} INFO - Task exited with return code 1
[2023-06-21 14:11:40,246] {local_task_job.py:273} INFO - 0 downstream tasks scheduled from follow-on schedule check
[2023-06-21 14:16:50,919] {taskinstance.py:1159} INFO - Dependencies all met for <TaskInstance: dados_climaticos.criar_pasta scheduled__2023-06-05T00:00:00+00:00 [queued]>
[2023-06-21 14:16:50,924] {taskinstance.py:1159} INFO - Dependencies all met for <TaskInstance: dados_climaticos.criar_pasta scheduled__2023-06-05T00:00:00+00:00 [queued]>
[2023-06-21 14:16:50,924] {taskinstance.py:1356} INFO - 
--------------------------------------------------------------------------------
[2023-06-21 14:16:50,924] {taskinstance.py:1357} INFO - Starting attempt 1 of 1
[2023-06-21 14:16:50,924] {taskinstance.py:1358} INFO - 
--------------------------------------------------------------------------------
[2023-06-21 14:16:50,935] {taskinstance.py:1377} INFO - Executing <Task(BashOperator): criar_pasta> on 2023-06-05 00:00:00+00:00
[2023-06-21 14:16:50,938] {standard_task_runner.py:52} INFO - Started process 88004 to run task
[2023-06-21 14:16:50,941] {standard_task_runner.py:79} INFO - Running: ['airflow', 'tasks', 'run', 'dados_climaticos', 'criar_pasta', 'scheduled__2023-06-05T00:00:00+00:00', '--job-id', '62', '--raw', '--subdir', 'DAGS_FOLDER/dados_climaticos.py', '--cfg-path', '/tmp/tmptm6qplou', '--error-file', '/tmp/tmpe6w7b2qi']
[2023-06-21 14:16:50,942] {standard_task_runner.py:80} INFO - Job 62: Subtask criar_pasta
[2023-06-21 14:16:50,976] {task_command.py:370} INFO - Running <TaskInstance: dados_climaticos.criar_pasta scheduled__2023-06-05T00:00:00+00:00 [running]> on host alura
[2023-06-21 14:16:50,995] {taskinstance.py:1889} ERROR - Task failed with exception
Traceback (most recent call last):
  File "/home/gilmar/Documentos/airflowalura/venv/lib/python3.9/site-packages/airflow/models/taskinstance.py", line 1451, in _run_raw_task
    self._execute_task_with_callbacks(context, test_mode)
  File "/home/gilmar/Documentos/airflowalura/venv/lib/python3.9/site-packages/airflow/models/taskinstance.py", line 1555, in _execute_task_with_callbacks
    task_orig = self.render_templates(context=context)
  File "/home/gilmar/Documentos/airflowalura/venv/lib/python3.9/site-packages/airflow/models/taskinstance.py", line 2212, in render_templates
    rendered_task = self.task.render_template_fields(context)
  File "/home/gilmar/Documentos/airflowalura/venv/lib/python3.9/site-packages/airflow/models/baseoperator.py", line 1185, in render_template_fields
    self._do_render_template_fields(self, self.template_fields, context, jinja_env, set())
  File "/home/gilmar/Documentos/airflowalura/venv/lib/python3.9/site-packages/airflow/utils/session.py", line 71, in wrapper
    return func(*args, session=session, **kwargs)
  File "/home/gilmar/Documentos/airflowalura/venv/lib/python3.9/site-packages/airflow/models/abstractoperator.py", line 344, in _do_render_template_fields
    rendered_content = self.render_template(
  File "/home/gilmar/Documentos/airflowalura/venv/lib/python3.9/site-packages/airflow/models/abstractoperator.py", line 387, in render_template
    template = jinja_env.from_string(value)
  File "/home/gilmar/Documentos/airflowalura/venv/lib/python3.9/site-packages/jinja2/environment.py", line 1092, in from_string
    return cls.from_code(self, self.compile(source), gs, None)
  File "/home/gilmar/Documentos/airflowalura/venv/lib/python3.9/site-packages/jinja2/environment.py", line 757, in compile
    self.handle_exception(source=source_hint)
  File "/home/gilmar/Documentos/airflowalura/venv/lib/python3.9/site-packages/jinja2/environment.py", line 925, in handle_exception
    raise rewrite_traceback_stack(source=source)
  File "<unknown>", line 1, in template
jinja2.exceptions.TemplateSyntaxError: unexpected end of template, expected ','.
[2023-06-21 14:16:50,999] {taskinstance.py:1395} INFO - Marking task as FAILED. dag_id=dados_climaticos, task_id=criar_pasta, execution_date=20230605T000000, start_date=20230621T171650, end_date=20230621T171650
[2023-06-21 14:16:51,012] {standard_task_runner.py:92} ERROR - Failed to execute job 62 for task criar_pasta (unexpected end of template, expected ','.; 88004)
[2023-06-21 14:16:51,036] {local_task_job.py:156} INFO - Task exited with return code 1
[2023-06-21 14:16:51,057] {local_task_job.py:273} INFO - 0 downstream tasks scheduled from follow-on schedule check
[2023-06-21 16:20:02,730] {taskinstance.py:1159} INFO - Dependencies all met for <TaskInstance: dados_climaticos.criar_pasta scheduled__2023-06-05T00:00:00+00:00 [queued]>
[2023-06-21 16:20:02,734] {taskinstance.py:1159} INFO - Dependencies all met for <TaskInstance: dados_climaticos.criar_pasta scheduled__2023-06-05T00:00:00+00:00 [queued]>
[2023-06-21 16:20:02,734] {taskinstance.py:1356} INFO - 
--------------------------------------------------------------------------------
[2023-06-21 16:20:02,735] {taskinstance.py:1357} INFO - Starting attempt 1 of 1
[2023-06-21 16:20:02,735] {taskinstance.py:1358} INFO - 
--------------------------------------------------------------------------------
[2023-06-21 16:20:02,744] {taskinstance.py:1377} INFO - Executing <Task(BashOperator): criar_pasta> on 2023-06-05 00:00:00+00:00
[2023-06-21 16:20:02,750] {standard_task_runner.py:52} INFO - Started process 6534 to run task
[2023-06-21 16:20:02,754] {standard_task_runner.py:79} INFO - Running: ['airflow', 'tasks', 'run', 'dados_climaticos', 'criar_pasta', 'scheduled__2023-06-05T00:00:00+00:00', '--job-id', '71', '--raw', '--subdir', 'DAGS_FOLDER/dados_climaticos.py', '--cfg-path', '/tmp/tmpsg0fgpuk', '--error-file', '/tmp/tmpdbkxo0vg']
[2023-06-21 16:20:02,756] {standard_task_runner.py:80} INFO - Job 71: Subtask criar_pasta
[2023-06-21 16:20:02,814] {task_command.py:370} INFO - Running <TaskInstance: dados_climaticos.criar_pasta scheduled__2023-06-05T00:00:00+00:00 [running]> on host alura
[2023-06-21 16:20:02,846] {taskinstance.py:1889} ERROR - Task failed with exception
Traceback (most recent call last):
  File "/home/gilmar/Documentos/airflowalura/venv/lib/python3.9/site-packages/airflow/models/taskinstance.py", line 1451, in _run_raw_task
    self._execute_task_with_callbacks(context, test_mode)
  File "/home/gilmar/Documentos/airflowalura/venv/lib/python3.9/site-packages/airflow/models/taskinstance.py", line 1555, in _execute_task_with_callbacks
    task_orig = self.render_templates(context=context)
  File "/home/gilmar/Documentos/airflowalura/venv/lib/python3.9/site-packages/airflow/models/taskinstance.py", line 2212, in render_templates
    rendered_task = self.task.render_template_fields(context)
  File "/home/gilmar/Documentos/airflowalura/venv/lib/python3.9/site-packages/airflow/models/baseoperator.py", line 1185, in render_template_fields
    self._do_render_template_fields(self, self.template_fields, context, jinja_env, set())
  File "/home/gilmar/Documentos/airflowalura/venv/lib/python3.9/site-packages/airflow/utils/session.py", line 71, in wrapper
    return func(*args, session=session, **kwargs)
  File "/home/gilmar/Documentos/airflowalura/venv/lib/python3.9/site-packages/airflow/models/abstractoperator.py", line 344, in _do_render_template_fields
    rendered_content = self.render_template(
  File "/home/gilmar/Documentos/airflowalura/venv/lib/python3.9/site-packages/airflow/models/abstractoperator.py", line 387, in render_template
    template = jinja_env.from_string(value)
  File "/home/gilmar/Documentos/airflowalura/venv/lib/python3.9/site-packages/jinja2/environment.py", line 1092, in from_string
    return cls.from_code(self, self.compile(source), gs, None)
  File "/home/gilmar/Documentos/airflowalura/venv/lib/python3.9/site-packages/jinja2/environment.py", line 757, in compile
    self.handle_exception(source=source_hint)
  File "/home/gilmar/Documentos/airflowalura/venv/lib/python3.9/site-packages/jinja2/environment.py", line 925, in handle_exception
    raise rewrite_traceback_stack(source=source)
  File "<unknown>", line 1, in template
jinja2.exceptions.TemplateSyntaxError: unexpected end of template, expected ','.
[2023-06-21 16:20:02,854] {taskinstance.py:1395} INFO - Marking task as FAILED. dag_id=dados_climaticos, task_id=criar_pasta, execution_date=20230605T000000, start_date=20230621T192002, end_date=20230621T192002
[2023-06-21 16:20:02,874] {standard_task_runner.py:92} ERROR - Failed to execute job 71 for task criar_pasta (unexpected end of template, expected ','.; 6534)
[2023-06-21 16:20:02,890] {local_task_job.py:156} INFO - Task exited with return code 1
[2023-06-21 16:20:02,917] {local_task_job.py:273} INFO - 0 downstream tasks scheduled from follow-on schedule check
