[2023-06-21 14:10:22,554] {taskinstance.py:1159} INFO - Dependencies all met for <TaskInstance: dados_climaticos.criar_pasta scheduled__2022-09-19T00:00:00+00:00 [queued]>
[2023-06-21 14:10:22,558] {taskinstance.py:1159} INFO - Dependencies all met for <TaskInstance: dados_climaticos.criar_pasta scheduled__2022-09-19T00:00:00+00:00 [queued]>
[2023-06-21 14:10:22,558] {taskinstance.py:1356} INFO - 
--------------------------------------------------------------------------------
[2023-06-21 14:10:22,558] {taskinstance.py:1357} INFO - Starting attempt 1 of 1
[2023-06-21 14:10:22,558] {taskinstance.py:1358} INFO - 
--------------------------------------------------------------------------------
[2023-06-21 14:10:22,567] {taskinstance.py:1377} INFO - Executing <Task(BashOperator): criar_pasta> on 2022-09-19 00:00:00+00:00
[2023-06-21 14:10:22,571] {standard_task_runner.py:52} INFO - Started process 87199 to run task
[2023-06-21 14:10:22,574] {standard_task_runner.py:79} INFO - Running: ['airflow', 'tasks', 'run', 'dados_climaticos', 'criar_pasta', 'scheduled__2022-09-19T00:00:00+00:00', '--job-id', '25', '--raw', '--subdir', 'DAGS_FOLDER/dados_climaticos.py', '--cfg-path', '/tmp/tmpmc52rahi', '--error-file', '/tmp/tmp6ic_umcx']
[2023-06-21 14:10:22,574] {standard_task_runner.py:80} INFO - Job 25: Subtask criar_pasta
[2023-06-21 14:10:22,606] {task_command.py:370} INFO - Running <TaskInstance: dados_climaticos.criar_pasta scheduled__2022-09-19T00:00:00+00:00 [running]> on host alura
[2023-06-21 14:10:22,624] {taskinstance.py:1889} ERROR - Task failed with exception
Traceback (most recent call last):
  File "/home/gilmar/Documentos/airflowalura/venv/lib/python3.9/site-packages/airflow/models/taskinstance.py", line 1451, in _run_raw_task
    self._execute_task_with_callbacks(context, test_mode)
  File "/home/gilmar/Documentos/airflowalura/venv/lib/python3.9/site-packages/airflow/models/taskinstance.py", line 1555, in _execute_task_with_callbacks
    task_orig = self.render_templates(context=context)
  File "/home/gilmar/Documentos/airflowalura/venv/lib/python3.9/site-packages/airflow/models/taskinstance.py", line 2212, in render_templates
    rendered_task = self.task.render_template_fields(context)
  File "/home/gilmar/Documentos/airflowalura/venv/lib/python3.9/site-packages/airflow/models/baseoperator.py", line 1185, in render_template_fields
    self._do_render_template_fields(self, self.template_fields, context, jinja_env, set())
  File "/home/gilmar/Documentos/airflowalura/venv/lib/python3.9/site-packages/airflow/utils/session.py", line 71, in wrapper
    return func(*args, session=session, **kwargs)
  File "/home/gilmar/Documentos/airflowalura/venv/lib/python3.9/site-packages/airflow/models/abstractoperator.py", line 344, in _do_render_template_fields
    rendered_content = self.render_template(
  File "/home/gilmar/Documentos/airflowalura/venv/lib/python3.9/site-packages/airflow/models/abstractoperator.py", line 387, in render_template
    template = jinja_env.from_string(value)
  File "/home/gilmar/Documentos/airflowalura/venv/lib/python3.9/site-packages/jinja2/environment.py", line 1092, in from_string
    return cls.from_code(self, self.compile(source), gs, None)
  File "/home/gilmar/Documentos/airflowalura/venv/lib/python3.9/site-packages/jinja2/environment.py", line 757, in compile
    self.handle_exception(source=source_hint)
  File "/home/gilmar/Documentos/airflowalura/venv/lib/python3.9/site-packages/jinja2/environment.py", line 925, in handle_exception
    raise rewrite_traceback_stack(source=source)
  File "<unknown>", line 1, in template
jinja2.exceptions.TemplateSyntaxError: unexpected end of template, expected ','.
[2023-06-21 14:10:22,628] {taskinstance.py:1395} INFO - Marking task as FAILED. dag_id=dados_climaticos, task_id=criar_pasta, execution_date=20220919T000000, start_date=20230621T171022, end_date=20230621T171022
[2023-06-21 14:10:22,636] {standard_task_runner.py:92} ERROR - Failed to execute job 25 for task criar_pasta (unexpected end of template, expected ','.; 87199)
[2023-06-21 14:10:22,670] {local_task_job.py:156} INFO - Task exited with return code 1
[2023-06-21 14:10:22,693] {local_task_job.py:273} INFO - 0 downstream tasks scheduled from follow-on schedule check
[2023-06-21 14:15:31,002] {taskinstance.py:1159} INFO - Dependencies all met for <TaskInstance: dados_climaticos.criar_pasta scheduled__2022-09-19T00:00:00+00:00 [queued]>
[2023-06-21 14:15:31,007] {taskinstance.py:1159} INFO - Dependencies all met for <TaskInstance: dados_climaticos.criar_pasta scheduled__2022-09-19T00:00:00+00:00 [queued]>
[2023-06-21 14:15:31,007] {taskinstance.py:1356} INFO - 
--------------------------------------------------------------------------------
[2023-06-21 14:15:31,007] {taskinstance.py:1357} INFO - Starting attempt 1 of 1
[2023-06-21 14:15:31,007] {taskinstance.py:1358} INFO - 
--------------------------------------------------------------------------------
[2023-06-21 14:15:31,016] {taskinstance.py:1377} INFO - Executing <Task(BashOperator): criar_pasta> on 2022-09-19 00:00:00+00:00
[2023-06-21 14:15:31,020] {standard_task_runner.py:52} INFO - Started process 87761 to run task
[2023-06-21 14:15:31,023] {standard_task_runner.py:79} INFO - Running: ['airflow', 'tasks', 'run', 'dados_climaticos', 'criar_pasta', 'scheduled__2022-09-19T00:00:00+00:00', '--job-id', '25', '--raw', '--subdir', 'DAGS_FOLDER/dados_climaticos.py', '--cfg-path', '/tmp/tmptesolq2w', '--error-file', '/tmp/tmpqpo6zg06']
[2023-06-21 14:15:31,024] {standard_task_runner.py:80} INFO - Job 25: Subtask criar_pasta
[2023-06-21 14:15:31,062] {task_command.py:370} INFO - Running <TaskInstance: dados_climaticos.criar_pasta scheduled__2022-09-19T00:00:00+00:00 [running]> on host alura
[2023-06-21 14:15:31,090] {taskinstance.py:1889} ERROR - Task failed with exception
Traceback (most recent call last):
  File "/home/gilmar/Documentos/airflowalura/venv/lib/python3.9/site-packages/airflow/models/taskinstance.py", line 1451, in _run_raw_task
    self._execute_task_with_callbacks(context, test_mode)
  File "/home/gilmar/Documentos/airflowalura/venv/lib/python3.9/site-packages/airflow/models/taskinstance.py", line 1555, in _execute_task_with_callbacks
    task_orig = self.render_templates(context=context)
  File "/home/gilmar/Documentos/airflowalura/venv/lib/python3.9/site-packages/airflow/models/taskinstance.py", line 2212, in render_templates
    rendered_task = self.task.render_template_fields(context)
  File "/home/gilmar/Documentos/airflowalura/venv/lib/python3.9/site-packages/airflow/models/baseoperator.py", line 1185, in render_template_fields
    self._do_render_template_fields(self, self.template_fields, context, jinja_env, set())
  File "/home/gilmar/Documentos/airflowalura/venv/lib/python3.9/site-packages/airflow/utils/session.py", line 71, in wrapper
    return func(*args, session=session, **kwargs)
  File "/home/gilmar/Documentos/airflowalura/venv/lib/python3.9/site-packages/airflow/models/abstractoperator.py", line 344, in _do_render_template_fields
    rendered_content = self.render_template(
  File "/home/gilmar/Documentos/airflowalura/venv/lib/python3.9/site-packages/airflow/models/abstractoperator.py", line 387, in render_template
    template = jinja_env.from_string(value)
  File "/home/gilmar/Documentos/airflowalura/venv/lib/python3.9/site-packages/jinja2/environment.py", line 1092, in from_string
    return cls.from_code(self, self.compile(source), gs, None)
  File "/home/gilmar/Documentos/airflowalura/venv/lib/python3.9/site-packages/jinja2/environment.py", line 757, in compile
    self.handle_exception(source=source_hint)
  File "/home/gilmar/Documentos/airflowalura/venv/lib/python3.9/site-packages/jinja2/environment.py", line 925, in handle_exception
    raise rewrite_traceback_stack(source=source)
  File "<unknown>", line 1, in template
jinja2.exceptions.TemplateSyntaxError: unexpected end of template, expected ','.
[2023-06-21 14:15:31,093] {taskinstance.py:1395} INFO - Marking task as FAILED. dag_id=dados_climaticos, task_id=criar_pasta, execution_date=20220919T000000, start_date=20230621T171531, end_date=20230621T171531
[2023-06-21 14:15:31,101] {standard_task_runner.py:92} ERROR - Failed to execute job 25 for task criar_pasta (unexpected end of template, expected ','.; 87761)
[2023-06-21 14:15:31,118] {local_task_job.py:156} INFO - Task exited with return code 1
[2023-06-21 14:15:31,140] {local_task_job.py:273} INFO - 0 downstream tasks scheduled from follow-on schedule check
