[2023-06-21 16:26:40,629] {taskinstance.py:1159} INFO - Dependencies all met for <TaskInstance: dados_climaticos.cria_pasta scheduled__2022-08-22T00:00:00+00:00 [queued]>
[2023-06-21 16:26:40,634] {taskinstance.py:1159} INFO - Dependencies all met for <TaskInstance: dados_climaticos.cria_pasta scheduled__2022-08-22T00:00:00+00:00 [queued]>
[2023-06-21 16:26:40,634] {taskinstance.py:1356} INFO - 
--------------------------------------------------------------------------------
[2023-06-21 16:26:40,635] {taskinstance.py:1357} INFO - Starting attempt 1 of 1
[2023-06-21 16:26:40,635] {taskinstance.py:1358} INFO - 
--------------------------------------------------------------------------------
[2023-06-21 16:26:40,651] {taskinstance.py:1377} INFO - Executing <Task(BashOperator): cria_pasta> on 2022-08-22 00:00:00+00:00
[2023-06-21 16:26:40,655] {standard_task_runner.py:52} INFO - Started process 8591 to run task
[2023-06-21 16:26:40,659] {standard_task_runner.py:79} INFO - Running: ['airflow', 'tasks', 'run', 'dados_climaticos', 'cria_pasta', 'scheduled__2022-08-22T00:00:00+00:00', '--job-id', '70', '--raw', '--subdir', 'DAGS_FOLDER/dados_climaticos.py', '--cfg-path', '/tmp/tmpproud7zg', '--error-file', '/tmp/tmprs4ndua0']
[2023-06-21 16:26:40,660] {standard_task_runner.py:80} INFO - Job 70: Subtask cria_pasta
[2023-06-21 16:26:40,700] {task_command.py:370} INFO - Running <TaskInstance: dados_climaticos.cria_pasta scheduled__2022-08-22T00:00:00+00:00 [running]> on host alura
[2023-06-21 16:26:40,723] {taskinstance.py:1889} ERROR - Task failed with exception
Traceback (most recent call last):
  File "/home/gilmar/Documentos/airflowalura/venv/lib/python3.9/site-packages/airflow/models/taskinstance.py", line 1451, in _run_raw_task
    self._execute_task_with_callbacks(context, test_mode)
  File "/home/gilmar/Documentos/airflowalura/venv/lib/python3.9/site-packages/airflow/models/taskinstance.py", line 1555, in _execute_task_with_callbacks
    task_orig = self.render_templates(context=context)
  File "/home/gilmar/Documentos/airflowalura/venv/lib/python3.9/site-packages/airflow/models/taskinstance.py", line 2212, in render_templates
    rendered_task = self.task.render_template_fields(context)
  File "/home/gilmar/Documentos/airflowalura/venv/lib/python3.9/site-packages/airflow/models/baseoperator.py", line 1185, in render_template_fields
    self._do_render_template_fields(self, self.template_fields, context, jinja_env, set())
  File "/home/gilmar/Documentos/airflowalura/venv/lib/python3.9/site-packages/airflow/utils/session.py", line 71, in wrapper
    return func(*args, session=session, **kwargs)
  File "/home/gilmar/Documentos/airflowalura/venv/lib/python3.9/site-packages/airflow/models/abstractoperator.py", line 344, in _do_render_template_fields
    rendered_content = self.render_template(
  File "/home/gilmar/Documentos/airflowalura/venv/lib/python3.9/site-packages/airflow/models/abstractoperator.py", line 387, in render_template
    template = jinja_env.from_string(value)
  File "/home/gilmar/Documentos/airflowalura/venv/lib/python3.9/site-packages/jinja2/environment.py", line 1092, in from_string
    return cls.from_code(self, self.compile(source), gs, None)
  File "/home/gilmar/Documentos/airflowalura/venv/lib/python3.9/site-packages/jinja2/environment.py", line 757, in compile
    self.handle_exception(source=source_hint)
  File "/home/gilmar/Documentos/airflowalura/venv/lib/python3.9/site-packages/jinja2/environment.py", line 925, in handle_exception
    raise rewrite_traceback_stack(source=source)
  File "<unknown>", line 1, in template
jinja2.exceptions.TemplateSyntaxError: unexpected end of template, expected ','.
[2023-06-21 16:26:40,727] {taskinstance.py:1395} INFO - Marking task as FAILED. dag_id=dados_climaticos, task_id=cria_pasta, execution_date=20220822T000000, start_date=20230621T192640, end_date=20230621T192640
[2023-06-21 16:26:40,736] {standard_task_runner.py:92} ERROR - Failed to execute job 70 for task cria_pasta (unexpected end of template, expected ','.; 8591)
[2023-06-21 16:26:40,754] {local_task_job.py:156} INFO - Task exited with return code 1
[2023-06-21 16:26:40,786] {local_task_job.py:273} INFO - 0 downstream tasks scheduled from follow-on schedule check
[2023-06-21 16:29:01,812] {taskinstance.py:1159} INFO - Dependencies all met for <TaskInstance: dados_climaticos.cria_pasta scheduled__2022-08-22T00:00:00+00:00 [queued]>
[2023-06-21 16:29:01,821] {taskinstance.py:1159} INFO - Dependencies all met for <TaskInstance: dados_climaticos.cria_pasta scheduled__2022-08-22T00:00:00+00:00 [queued]>
[2023-06-21 16:29:01,821] {taskinstance.py:1356} INFO - 
--------------------------------------------------------------------------------
[2023-06-21 16:29:01,821] {taskinstance.py:1357} INFO - Starting attempt 1 of 1
[2023-06-21 16:29:01,821] {taskinstance.py:1358} INFO - 
--------------------------------------------------------------------------------
[2023-06-21 16:29:01,830] {taskinstance.py:1377} INFO - Executing <Task(BashOperator): cria_pasta> on 2022-08-22 00:00:00+00:00
[2023-06-21 16:29:01,833] {standard_task_runner.py:52} INFO - Started process 9376 to run task
[2023-06-21 16:29:01,837] {standard_task_runner.py:79} INFO - Running: ['airflow', 'tasks', 'run', 'dados_climaticos', 'cria_pasta', 'scheduled__2022-08-22T00:00:00+00:00', '--job-id', '70', '--raw', '--subdir', 'DAGS_FOLDER/dados_climaticos_OLD.py', '--cfg-path', '/tmp/tmpt2lv3179', '--error-file', '/tmp/tmp87nr0vl4']
[2023-06-21 16:29:01,838] {standard_task_runner.py:80} INFO - Job 70: Subtask cria_pasta
[2023-06-21 16:29:01,869] {task_command.py:370} INFO - Running <TaskInstance: dados_climaticos.cria_pasta scheduled__2022-08-22T00:00:00+00:00 [running]> on host alura
[2023-06-21 16:29:01,890] {taskinstance.py:1889} ERROR - Task failed with exception
Traceback (most recent call last):
  File "/home/gilmar/Documentos/airflowalura/venv/lib/python3.9/site-packages/airflow/models/taskinstance.py", line 1451, in _run_raw_task
    self._execute_task_with_callbacks(context, test_mode)
  File "/home/gilmar/Documentos/airflowalura/venv/lib/python3.9/site-packages/airflow/models/taskinstance.py", line 1555, in _execute_task_with_callbacks
    task_orig = self.render_templates(context=context)
  File "/home/gilmar/Documentos/airflowalura/venv/lib/python3.9/site-packages/airflow/models/taskinstance.py", line 2212, in render_templates
    rendered_task = self.task.render_template_fields(context)
  File "/home/gilmar/Documentos/airflowalura/venv/lib/python3.9/site-packages/airflow/models/baseoperator.py", line 1185, in render_template_fields
    self._do_render_template_fields(self, self.template_fields, context, jinja_env, set())
  File "/home/gilmar/Documentos/airflowalura/venv/lib/python3.9/site-packages/airflow/utils/session.py", line 71, in wrapper
    return func(*args, session=session, **kwargs)
  File "/home/gilmar/Documentos/airflowalura/venv/lib/python3.9/site-packages/airflow/models/abstractoperator.py", line 344, in _do_render_template_fields
    rendered_content = self.render_template(
  File "/home/gilmar/Documentos/airflowalura/venv/lib/python3.9/site-packages/airflow/models/abstractoperator.py", line 387, in render_template
    template = jinja_env.from_string(value)
  File "/home/gilmar/Documentos/airflowalura/venv/lib/python3.9/site-packages/jinja2/environment.py", line 1092, in from_string
    return cls.from_code(self, self.compile(source), gs, None)
  File "/home/gilmar/Documentos/airflowalura/venv/lib/python3.9/site-packages/jinja2/environment.py", line 757, in compile
    self.handle_exception(source=source_hint)
  File "/home/gilmar/Documentos/airflowalura/venv/lib/python3.9/site-packages/jinja2/environment.py", line 925, in handle_exception
    raise rewrite_traceback_stack(source=source)
  File "<unknown>", line 1, in template
jinja2.exceptions.TemplateSyntaxError: unexpected end of template, expected ','.
[2023-06-21 16:29:01,894] {taskinstance.py:1395} INFO - Marking task as FAILED. dag_id=dados_climaticos, task_id=cria_pasta, execution_date=20220822T000000, start_date=20230621T192901, end_date=20230621T192901
[2023-06-21 16:29:01,905] {standard_task_runner.py:92} ERROR - Failed to execute job 70 for task cria_pasta (unexpected end of template, expected ','.; 9376)
[2023-06-21 16:29:01,932] {local_task_job.py:156} INFO - Task exited with return code 1
[2023-06-21 16:29:01,975] {local_task_job.py:273} INFO - 0 downstream tasks scheduled from follow-on schedule check
[2023-06-21 16:30:49,675] {taskinstance.py:1159} INFO - Dependencies all met for <TaskInstance: dados_climaticos.cria_pasta scheduled__2022-08-22T00:00:00+00:00 [queued]>
[2023-06-21 16:30:49,679] {taskinstance.py:1159} INFO - Dependencies all met for <TaskInstance: dados_climaticos.cria_pasta scheduled__2022-08-22T00:00:00+00:00 [queued]>
[2023-06-21 16:30:49,679] {taskinstance.py:1356} INFO - 
--------------------------------------------------------------------------------
[2023-06-21 16:30:49,679] {taskinstance.py:1357} INFO - Starting attempt 1 of 1
[2023-06-21 16:30:49,679] {taskinstance.py:1358} INFO - 
--------------------------------------------------------------------------------
[2023-06-21 16:30:49,693] {taskinstance.py:1377} INFO - Executing <Task(BashOperator): cria_pasta> on 2022-08-22 00:00:00+00:00
[2023-06-21 16:30:49,697] {standard_task_runner.py:52} INFO - Started process 10056 to run task
[2023-06-21 16:30:49,700] {standard_task_runner.py:79} INFO - Running: ['airflow', 'tasks', 'run', 'dados_climaticos', 'cria_pasta', 'scheduled__2022-08-22T00:00:00+00:00', '--job-id', '70', '--raw', '--subdir', 'DAGS_FOLDER/dados_climaticos_OLD.py', '--cfg-path', '/tmp/tmp2hd9qt2s', '--error-file', '/tmp/tmpzmrt5cok']
[2023-06-21 16:30:49,701] {standard_task_runner.py:80} INFO - Job 70: Subtask cria_pasta
[2023-06-21 16:30:49,732] {task_command.py:370} INFO - Running <TaskInstance: dados_climaticos.cria_pasta scheduled__2022-08-22T00:00:00+00:00 [running]> on host alura
[2023-06-21 16:30:49,751] {taskinstance.py:1889} ERROR - Task failed with exception
Traceback (most recent call last):
  File "/home/gilmar/Documentos/airflowalura/venv/lib/python3.9/site-packages/airflow/models/taskinstance.py", line 1451, in _run_raw_task
    self._execute_task_with_callbacks(context, test_mode)
  File "/home/gilmar/Documentos/airflowalura/venv/lib/python3.9/site-packages/airflow/models/taskinstance.py", line 1555, in _execute_task_with_callbacks
    task_orig = self.render_templates(context=context)
  File "/home/gilmar/Documentos/airflowalura/venv/lib/python3.9/site-packages/airflow/models/taskinstance.py", line 2212, in render_templates
    rendered_task = self.task.render_template_fields(context)
  File "/home/gilmar/Documentos/airflowalura/venv/lib/python3.9/site-packages/airflow/models/baseoperator.py", line 1185, in render_template_fields
    self._do_render_template_fields(self, self.template_fields, context, jinja_env, set())
  File "/home/gilmar/Documentos/airflowalura/venv/lib/python3.9/site-packages/airflow/utils/session.py", line 71, in wrapper
    return func(*args, session=session, **kwargs)
  File "/home/gilmar/Documentos/airflowalura/venv/lib/python3.9/site-packages/airflow/models/abstractoperator.py", line 344, in _do_render_template_fields
    rendered_content = self.render_template(
  File "/home/gilmar/Documentos/airflowalura/venv/lib/python3.9/site-packages/airflow/models/abstractoperator.py", line 387, in render_template
    template = jinja_env.from_string(value)
  File "/home/gilmar/Documentos/airflowalura/venv/lib/python3.9/site-packages/jinja2/environment.py", line 1092, in from_string
    return cls.from_code(self, self.compile(source), gs, None)
  File "/home/gilmar/Documentos/airflowalura/venv/lib/python3.9/site-packages/jinja2/environment.py", line 757, in compile
    self.handle_exception(source=source_hint)
  File "/home/gilmar/Documentos/airflowalura/venv/lib/python3.9/site-packages/jinja2/environment.py", line 925, in handle_exception
    raise rewrite_traceback_stack(source=source)
  File "<unknown>", line 1, in template
jinja2.exceptions.TemplateSyntaxError: unexpected end of template, expected ','.
[2023-06-21 16:30:49,755] {taskinstance.py:1395} INFO - Marking task as FAILED. dag_id=dados_climaticos, task_id=cria_pasta, execution_date=20220822T000000, start_date=20230621T193049, end_date=20230621T193049
[2023-06-21 16:30:49,765] {standard_task_runner.py:92} ERROR - Failed to execute job 70 for task cria_pasta (unexpected end of template, expected ','.; 10056)
[2023-06-21 16:30:49,795] {local_task_job.py:156} INFO - Task exited with return code 1
[2023-06-21 16:30:49,831] {local_task_job.py:273} INFO - 0 downstream tasks scheduled from follow-on schedule check
[2023-06-22 10:18:22,576] {taskinstance.py:1159} INFO - Dependencies all met for <TaskInstance: dados_climaticos.cria_pasta scheduled__2022-08-22T00:00:00+00:00 [queued]>
[2023-06-22 10:18:22,587] {taskinstance.py:1159} INFO - Dependencies all met for <TaskInstance: dados_climaticos.cria_pasta scheduled__2022-08-22T00:00:00+00:00 [queued]>
[2023-06-22 10:18:22,588] {taskinstance.py:1356} INFO - 
--------------------------------------------------------------------------------
[2023-06-22 10:18:22,588] {taskinstance.py:1357} INFO - Starting attempt 1 of 1
[2023-06-22 10:18:22,588] {taskinstance.py:1358} INFO - 
--------------------------------------------------------------------------------
[2023-06-22 10:18:22,596] {taskinstance.py:1377} INFO - Executing <Task(BashOperator): cria_pasta> on 2022-08-22 00:00:00+00:00
[2023-06-22 10:18:22,599] {standard_task_runner.py:52} INFO - Started process 8759 to run task
[2023-06-22 10:18:22,602] {standard_task_runner.py:79} INFO - Running: ['airflow', 'tasks', 'run', 'dados_climaticos', 'cria_pasta', 'scheduled__2022-08-22T00:00:00+00:00', '--job-id', '140', '--raw', '--subdir', 'DAGS_FOLDER/dados_climaticos_OLD.py', '--cfg-path', '/tmp/tmpz4urskno', '--error-file', '/tmp/tmpkf7vm5pr']
[2023-06-22 10:18:22,603] {standard_task_runner.py:80} INFO - Job 140: Subtask cria_pasta
[2023-06-22 10:18:22,637] {task_command.py:370} INFO - Running <TaskInstance: dados_climaticos.cria_pasta scheduled__2022-08-22T00:00:00+00:00 [running]> on host alura
[2023-06-22 10:18:22,659] {taskinstance.py:1889} ERROR - Task failed with exception
Traceback (most recent call last):
  File "/home/gilmar/Documentos/airflowalura/venv/lib/python3.9/site-packages/airflow/models/taskinstance.py", line 1451, in _run_raw_task
    self._execute_task_with_callbacks(context, test_mode)
  File "/home/gilmar/Documentos/airflowalura/venv/lib/python3.9/site-packages/airflow/models/taskinstance.py", line 1555, in _execute_task_with_callbacks
    task_orig = self.render_templates(context=context)
  File "/home/gilmar/Documentos/airflowalura/venv/lib/python3.9/site-packages/airflow/models/taskinstance.py", line 2212, in render_templates
    rendered_task = self.task.render_template_fields(context)
  File "/home/gilmar/Documentos/airflowalura/venv/lib/python3.9/site-packages/airflow/models/baseoperator.py", line 1185, in render_template_fields
    self._do_render_template_fields(self, self.template_fields, context, jinja_env, set())
  File "/home/gilmar/Documentos/airflowalura/venv/lib/python3.9/site-packages/airflow/utils/session.py", line 71, in wrapper
    return func(*args, session=session, **kwargs)
  File "/home/gilmar/Documentos/airflowalura/venv/lib/python3.9/site-packages/airflow/models/abstractoperator.py", line 344, in _do_render_template_fields
    rendered_content = self.render_template(
  File "/home/gilmar/Documentos/airflowalura/venv/lib/python3.9/site-packages/airflow/models/abstractoperator.py", line 387, in render_template
    template = jinja_env.from_string(value)
  File "/home/gilmar/Documentos/airflowalura/venv/lib/python3.9/site-packages/jinja2/environment.py", line 1092, in from_string
    return cls.from_code(self, self.compile(source), gs, None)
  File "/home/gilmar/Documentos/airflowalura/venv/lib/python3.9/site-packages/jinja2/environment.py", line 757, in compile
    self.handle_exception(source=source_hint)
  File "/home/gilmar/Documentos/airflowalura/venv/lib/python3.9/site-packages/jinja2/environment.py", line 925, in handle_exception
    raise rewrite_traceback_stack(source=source)
  File "<unknown>", line 1, in template
jinja2.exceptions.TemplateSyntaxError: unexpected end of template, expected ','.
[2023-06-22 10:18:22,663] {taskinstance.py:1395} INFO - Marking task as FAILED. dag_id=dados_climaticos, task_id=cria_pasta, execution_date=20220822T000000, start_date=20230622T131822, end_date=20230622T131822
[2023-06-22 10:18:22,672] {standard_task_runner.py:92} ERROR - Failed to execute job 140 for task cria_pasta (unexpected end of template, expected ','.; 8759)
[2023-06-22 10:18:22,697] {local_task_job.py:156} INFO - Task exited with return code 1
[2023-06-22 10:18:22,724] {local_task_job.py:273} INFO - 0 downstream tasks scheduled from follow-on schedule check
