[2023-06-21 16:26:47,250] {taskinstance.py:1159} INFO - Dependencies all met for <TaskInstance: dados_climaticos.cria_pasta scheduled__2022-09-12T00:00:00+00:00 [queued]>
[2023-06-21 16:26:47,256] {taskinstance.py:1159} INFO - Dependencies all met for <TaskInstance: dados_climaticos.cria_pasta scheduled__2022-09-12T00:00:00+00:00 [queued]>
[2023-06-21 16:26:47,256] {taskinstance.py:1356} INFO - 
--------------------------------------------------------------------------------
[2023-06-21 16:26:47,256] {taskinstance.py:1357} INFO - Starting attempt 1 of 1
[2023-06-21 16:26:47,256] {taskinstance.py:1358} INFO - 
--------------------------------------------------------------------------------
[2023-06-21 16:26:47,267] {taskinstance.py:1377} INFO - Executing <Task(BashOperator): cria_pasta> on 2022-09-12 00:00:00+00:00
[2023-06-21 16:26:47,275] {standard_task_runner.py:52} INFO - Started process 8648 to run task
[2023-06-21 16:26:47,280] {standard_task_runner.py:79} INFO - Running: ['airflow', 'tasks', 'run', 'dados_climaticos', 'cria_pasta', 'scheduled__2022-09-12T00:00:00+00:00', '--job-id', '73', '--raw', '--subdir', 'DAGS_FOLDER/dados_climaticos.py', '--cfg-path', '/tmp/tmpptzydw86', '--error-file', '/tmp/tmpmfc40154']
[2023-06-21 16:26:47,280] {standard_task_runner.py:80} INFO - Job 73: Subtask cria_pasta
[2023-06-21 16:26:47,316] {task_command.py:370} INFO - Running <TaskInstance: dados_climaticos.cria_pasta scheduled__2022-09-12T00:00:00+00:00 [running]> on host alura
[2023-06-21 16:26:47,336] {taskinstance.py:1889} ERROR - Task failed with exception
Traceback (most recent call last):
  File "/home/gilmar/Documentos/airflowalura/venv/lib/python3.9/site-packages/airflow/models/taskinstance.py", line 1451, in _run_raw_task
    self._execute_task_with_callbacks(context, test_mode)
  File "/home/gilmar/Documentos/airflowalura/venv/lib/python3.9/site-packages/airflow/models/taskinstance.py", line 1555, in _execute_task_with_callbacks
    task_orig = self.render_templates(context=context)
  File "/home/gilmar/Documentos/airflowalura/venv/lib/python3.9/site-packages/airflow/models/taskinstance.py", line 2212, in render_templates
    rendered_task = self.task.render_template_fields(context)
  File "/home/gilmar/Documentos/airflowalura/venv/lib/python3.9/site-packages/airflow/models/baseoperator.py", line 1185, in render_template_fields
    self._do_render_template_fields(self, self.template_fields, context, jinja_env, set())
  File "/home/gilmar/Documentos/airflowalura/venv/lib/python3.9/site-packages/airflow/utils/session.py", line 71, in wrapper
    return func(*args, session=session, **kwargs)
  File "/home/gilmar/Documentos/airflowalura/venv/lib/python3.9/site-packages/airflow/models/abstractoperator.py", line 344, in _do_render_template_fields
    rendered_content = self.render_template(
  File "/home/gilmar/Documentos/airflowalura/venv/lib/python3.9/site-packages/airflow/models/abstractoperator.py", line 387, in render_template
    template = jinja_env.from_string(value)
  File "/home/gilmar/Documentos/airflowalura/venv/lib/python3.9/site-packages/jinja2/environment.py", line 1092, in from_string
    return cls.from_code(self, self.compile(source), gs, None)
  File "/home/gilmar/Documentos/airflowalura/venv/lib/python3.9/site-packages/jinja2/environment.py", line 757, in compile
    self.handle_exception(source=source_hint)
  File "/home/gilmar/Documentos/airflowalura/venv/lib/python3.9/site-packages/jinja2/environment.py", line 925, in handle_exception
    raise rewrite_traceback_stack(source=source)
  File "<unknown>", line 1, in template
jinja2.exceptions.TemplateSyntaxError: unexpected end of template, expected ','.
[2023-06-21 16:26:47,341] {taskinstance.py:1395} INFO - Marking task as FAILED. dag_id=dados_climaticos, task_id=cria_pasta, execution_date=20220912T000000, start_date=20230621T192647, end_date=20230621T192647
[2023-06-21 16:26:47,350] {standard_task_runner.py:92} ERROR - Failed to execute job 73 for task cria_pasta (unexpected end of template, expected ','.; 8648)
[2023-06-21 16:26:47,377] {local_task_job.py:156} INFO - Task exited with return code 1
[2023-06-21 16:26:47,410] {local_task_job.py:273} INFO - 0 downstream tasks scheduled from follow-on schedule check
[2023-06-21 16:29:10,603] {taskinstance.py:1159} INFO - Dependencies all met for <TaskInstance: dados_climaticos.cria_pasta scheduled__2022-09-12T00:00:00+00:00 [queued]>
[2023-06-21 16:29:10,608] {taskinstance.py:1159} INFO - Dependencies all met for <TaskInstance: dados_climaticos.cria_pasta scheduled__2022-09-12T00:00:00+00:00 [queued]>
[2023-06-21 16:29:10,608] {taskinstance.py:1356} INFO - 
--------------------------------------------------------------------------------
[2023-06-21 16:29:10,608] {taskinstance.py:1357} INFO - Starting attempt 1 of 1
[2023-06-21 16:29:10,608] {taskinstance.py:1358} INFO - 
--------------------------------------------------------------------------------
[2023-06-21 16:29:10,617] {taskinstance.py:1377} INFO - Executing <Task(BashOperator): cria_pasta> on 2022-09-12 00:00:00+00:00
[2023-06-21 16:29:10,620] {standard_task_runner.py:52} INFO - Started process 9444 to run task
[2023-06-21 16:29:10,623] {standard_task_runner.py:79} INFO - Running: ['airflow', 'tasks', 'run', 'dados_climaticos', 'cria_pasta', 'scheduled__2022-09-12T00:00:00+00:00', '--job-id', '74', '--raw', '--subdir', 'DAGS_FOLDER/dados_climaticos.py', '--cfg-path', '/tmp/tmpquosg5s6', '--error-file', '/tmp/tmpdh7u4dak']
[2023-06-21 16:29:10,624] {standard_task_runner.py:80} INFO - Job 74: Subtask cria_pasta
[2023-06-21 16:29:10,656] {task_command.py:370} INFO - Running <TaskInstance: dados_climaticos.cria_pasta scheduled__2022-09-12T00:00:00+00:00 [running]> on host alura
[2023-06-21 16:29:10,698] {taskinstance.py:1569} INFO - Exporting the following env vars:
AIRFLOW_CTX_DAG_OWNER=airflow
AIRFLOW_CTX_DAG_ID=dados_climaticos
AIRFLOW_CTX_TASK_ID=cria_pasta
AIRFLOW_CTX_EXECUTION_DATE=2022-09-12T00:00:00+00:00
AIRFLOW_CTX_TRY_NUMBER=1
AIRFLOW_CTX_DAG_RUN_ID=scheduled__2022-09-12T00:00:00+00:00
[2023-06-21 16:29:10,699] {subprocess.py:62} INFO - Tmp dir root location: 
 /tmp
[2023-06-21 16:29:10,700] {subprocess.py:74} INFO - Running command: ['bash', '-c', 'mkdir -p "/home/gilmar/Documentos/airflowalura/semana=2022-09-19"']
[2023-06-21 16:29:10,707] {subprocess.py:85} INFO - Output:
[2023-06-21 16:29:10,709] {subprocess.py:96} INFO - Command exited with return code 0
[2023-06-21 16:29:10,731] {taskinstance.py:1395} INFO - Marking task as SUCCESS. dag_id=dados_climaticos, task_id=cria_pasta, execution_date=20220912T000000, start_date=20230621T192910, end_date=20230621T192910
[2023-06-21 16:29:10,760] {local_task_job.py:156} INFO - Task exited with return code 0
[2023-06-21 16:29:10,783] {local_task_job.py:273} INFO - 1 downstream tasks scheduled from follow-on schedule check
[2023-06-21 16:30:56,176] {taskinstance.py:1159} INFO - Dependencies all met for <TaskInstance: dados_climaticos.cria_pasta scheduled__2022-09-12T00:00:00+00:00 [queued]>
[2023-06-21 16:30:56,180] {taskinstance.py:1159} INFO - Dependencies all met for <TaskInstance: dados_climaticos.cria_pasta scheduled__2022-09-12T00:00:00+00:00 [queued]>
[2023-06-21 16:30:56,180] {taskinstance.py:1356} INFO - 
--------------------------------------------------------------------------------
[2023-06-21 16:30:56,180] {taskinstance.py:1357} INFO - Starting attempt 1 of 1
[2023-06-21 16:30:56,180] {taskinstance.py:1358} INFO - 
--------------------------------------------------------------------------------
[2023-06-21 16:30:56,190] {taskinstance.py:1377} INFO - Executing <Task(BashOperator): cria_pasta> on 2022-09-12 00:00:00+00:00
[2023-06-21 16:30:56,194] {standard_task_runner.py:52} INFO - Started process 10109 to run task
[2023-06-21 16:30:56,197] {standard_task_runner.py:79} INFO - Running: ['airflow', 'tasks', 'run', 'dados_climaticos', 'cria_pasta', 'scheduled__2022-09-12T00:00:00+00:00', '--job-id', '73', '--raw', '--subdir', 'DAGS_FOLDER/dados_climaticos_OLD.py', '--cfg-path', '/tmp/tmpaibibupw', '--error-file', '/tmp/tmps9gvfbu9']
[2023-06-21 16:30:56,197] {standard_task_runner.py:80} INFO - Job 73: Subtask cria_pasta
[2023-06-21 16:30:56,231] {task_command.py:370} INFO - Running <TaskInstance: dados_climaticos.cria_pasta scheduled__2022-09-12T00:00:00+00:00 [running]> on host alura
[2023-06-21 16:30:56,249] {taskinstance.py:1889} ERROR - Task failed with exception
Traceback (most recent call last):
  File "/home/gilmar/Documentos/airflowalura/venv/lib/python3.9/site-packages/airflow/models/taskinstance.py", line 1451, in _run_raw_task
    self._execute_task_with_callbacks(context, test_mode)
  File "/home/gilmar/Documentos/airflowalura/venv/lib/python3.9/site-packages/airflow/models/taskinstance.py", line 1555, in _execute_task_with_callbacks
    task_orig = self.render_templates(context=context)
  File "/home/gilmar/Documentos/airflowalura/venv/lib/python3.9/site-packages/airflow/models/taskinstance.py", line 2212, in render_templates
    rendered_task = self.task.render_template_fields(context)
  File "/home/gilmar/Documentos/airflowalura/venv/lib/python3.9/site-packages/airflow/models/baseoperator.py", line 1185, in render_template_fields
    self._do_render_template_fields(self, self.template_fields, context, jinja_env, set())
  File "/home/gilmar/Documentos/airflowalura/venv/lib/python3.9/site-packages/airflow/utils/session.py", line 71, in wrapper
    return func(*args, session=session, **kwargs)
  File "/home/gilmar/Documentos/airflowalura/venv/lib/python3.9/site-packages/airflow/models/abstractoperator.py", line 344, in _do_render_template_fields
    rendered_content = self.render_template(
  File "/home/gilmar/Documentos/airflowalura/venv/lib/python3.9/site-packages/airflow/models/abstractoperator.py", line 387, in render_template
    template = jinja_env.from_string(value)
  File "/home/gilmar/Documentos/airflowalura/venv/lib/python3.9/site-packages/jinja2/environment.py", line 1092, in from_string
    return cls.from_code(self, self.compile(source), gs, None)
  File "/home/gilmar/Documentos/airflowalura/venv/lib/python3.9/site-packages/jinja2/environment.py", line 757, in compile
    self.handle_exception(source=source_hint)
  File "/home/gilmar/Documentos/airflowalura/venv/lib/python3.9/site-packages/jinja2/environment.py", line 925, in handle_exception
    raise rewrite_traceback_stack(source=source)
  File "<unknown>", line 1, in template
jinja2.exceptions.TemplateSyntaxError: unexpected end of template, expected ','.
[2023-06-21 16:30:56,254] {taskinstance.py:1395} INFO - Marking task as FAILED. dag_id=dados_climaticos, task_id=cria_pasta, execution_date=20220912T000000, start_date=20230621T193056, end_date=20230621T193056
[2023-06-21 16:30:56,261] {standard_task_runner.py:92} ERROR - Failed to execute job 73 for task cria_pasta (unexpected end of template, expected ','.; 10109)
[2023-06-21 16:30:56,293] {local_task_job.py:156} INFO - Task exited with return code 1
[2023-06-21 16:30:56,321] {local_task_job.py:273} INFO - 0 downstream tasks scheduled from follow-on schedule check
[2023-06-22 10:18:29,115] {taskinstance.py:1159} INFO - Dependencies all met for <TaskInstance: dados_climaticos.cria_pasta scheduled__2022-09-12T00:00:00+00:00 [queued]>
[2023-06-22 10:18:29,123] {taskinstance.py:1159} INFO - Dependencies all met for <TaskInstance: dados_climaticos.cria_pasta scheduled__2022-09-12T00:00:00+00:00 [queued]>
[2023-06-22 10:18:29,124] {taskinstance.py:1356} INFO - 
--------------------------------------------------------------------------------
[2023-06-22 10:18:29,124] {taskinstance.py:1357} INFO - Starting attempt 1 of 1
[2023-06-22 10:18:29,124] {taskinstance.py:1358} INFO - 
--------------------------------------------------------------------------------
[2023-06-22 10:18:29,138] {taskinstance.py:1377} INFO - Executing <Task(BashOperator): cria_pasta> on 2022-09-12 00:00:00+00:00
[2023-06-22 10:18:29,141] {standard_task_runner.py:52} INFO - Started process 8814 to run task
[2023-06-22 10:18:29,144] {standard_task_runner.py:79} INFO - Running: ['airflow', 'tasks', 'run', 'dados_climaticos', 'cria_pasta', 'scheduled__2022-09-12T00:00:00+00:00', '--job-id', '143', '--raw', '--subdir', 'DAGS_FOLDER/dados_climaticos_OLD.py', '--cfg-path', '/tmp/tmpvyj2rd_d', '--error-file', '/tmp/tmpth16xs4b']
[2023-06-22 10:18:29,145] {standard_task_runner.py:80} INFO - Job 143: Subtask cria_pasta
[2023-06-22 10:18:29,177] {task_command.py:370} INFO - Running <TaskInstance: dados_climaticos.cria_pasta scheduled__2022-09-12T00:00:00+00:00 [running]> on host alura
[2023-06-22 10:18:29,196] {taskinstance.py:1889} ERROR - Task failed with exception
Traceback (most recent call last):
  File "/home/gilmar/Documentos/airflowalura/venv/lib/python3.9/site-packages/airflow/models/taskinstance.py", line 1451, in _run_raw_task
    self._execute_task_with_callbacks(context, test_mode)
  File "/home/gilmar/Documentos/airflowalura/venv/lib/python3.9/site-packages/airflow/models/taskinstance.py", line 1555, in _execute_task_with_callbacks
    task_orig = self.render_templates(context=context)
  File "/home/gilmar/Documentos/airflowalura/venv/lib/python3.9/site-packages/airflow/models/taskinstance.py", line 2212, in render_templates
    rendered_task = self.task.render_template_fields(context)
  File "/home/gilmar/Documentos/airflowalura/venv/lib/python3.9/site-packages/airflow/models/baseoperator.py", line 1185, in render_template_fields
    self._do_render_template_fields(self, self.template_fields, context, jinja_env, set())
  File "/home/gilmar/Documentos/airflowalura/venv/lib/python3.9/site-packages/airflow/utils/session.py", line 71, in wrapper
    return func(*args, session=session, **kwargs)
  File "/home/gilmar/Documentos/airflowalura/venv/lib/python3.9/site-packages/airflow/models/abstractoperator.py", line 344, in _do_render_template_fields
    rendered_content = self.render_template(
  File "/home/gilmar/Documentos/airflowalura/venv/lib/python3.9/site-packages/airflow/models/abstractoperator.py", line 387, in render_template
    template = jinja_env.from_string(value)
  File "/home/gilmar/Documentos/airflowalura/venv/lib/python3.9/site-packages/jinja2/environment.py", line 1092, in from_string
    return cls.from_code(self, self.compile(source), gs, None)
  File "/home/gilmar/Documentos/airflowalura/venv/lib/python3.9/site-packages/jinja2/environment.py", line 757, in compile
    self.handle_exception(source=source_hint)
  File "/home/gilmar/Documentos/airflowalura/venv/lib/python3.9/site-packages/jinja2/environment.py", line 925, in handle_exception
    raise rewrite_traceback_stack(source=source)
  File "<unknown>", line 1, in template
jinja2.exceptions.TemplateSyntaxError: unexpected end of template, expected ','.
[2023-06-22 10:18:29,201] {taskinstance.py:1395} INFO - Marking task as FAILED. dag_id=dados_climaticos, task_id=cria_pasta, execution_date=20220912T000000, start_date=20230622T131829, end_date=20230622T131829
[2023-06-22 10:18:29,212] {standard_task_runner.py:92} ERROR - Failed to execute job 143 for task cria_pasta (unexpected end of template, expected ','.; 8814)
[2023-06-22 10:18:29,241] {local_task_job.py:156} INFO - Task exited with return code 1
[2023-06-22 10:18:29,268] {local_task_job.py:273} INFO - 0 downstream tasks scheduled from follow-on schedule check
