[2023-06-21 16:29:23,662] {taskinstance.py:1159} INFO - Dependencies all met for <TaskInstance: dados_climaticos.cria_pasta scheduled__2022-10-03T00:00:00+00:00 [queued]>
[2023-06-21 16:29:23,668] {taskinstance.py:1159} INFO - Dependencies all met for <TaskInstance: dados_climaticos.cria_pasta scheduled__2022-10-03T00:00:00+00:00 [queued]>
[2023-06-21 16:29:23,668] {taskinstance.py:1356} INFO - 
--------------------------------------------------------------------------------
[2023-06-21 16:29:23,668] {taskinstance.py:1357} INFO - Starting attempt 1 of 1
[2023-06-21 16:29:23,668] {taskinstance.py:1358} INFO - 
--------------------------------------------------------------------------------
[2023-06-21 16:29:23,679] {taskinstance.py:1377} INFO - Executing <Task(BashOperator): cria_pasta> on 2022-10-03 00:00:00+00:00
[2023-06-21 16:29:23,683] {standard_task_runner.py:52} INFO - Started process 9555 to run task
[2023-06-21 16:29:23,687] {standard_task_runner.py:79} INFO - Running: ['airflow', 'tasks', 'run', 'dados_climaticos', 'cria_pasta', 'scheduled__2022-10-03T00:00:00+00:00', '--job-id', '80', '--raw', '--subdir', 'DAGS_FOLDER/dados_climaticos.py', '--cfg-path', '/tmp/tmp04dnjxrr', '--error-file', '/tmp/tmp32gifm6_']
[2023-06-21 16:29:23,688] {standard_task_runner.py:80} INFO - Job 80: Subtask cria_pasta
[2023-06-21 16:29:23,723] {task_command.py:370} INFO - Running <TaskInstance: dados_climaticos.cria_pasta scheduled__2022-10-03T00:00:00+00:00 [running]> on host alura
[2023-06-21 16:29:23,766] {taskinstance.py:1569} INFO - Exporting the following env vars:
AIRFLOW_CTX_DAG_OWNER=airflow
AIRFLOW_CTX_DAG_ID=dados_climaticos
AIRFLOW_CTX_TASK_ID=cria_pasta
AIRFLOW_CTX_EXECUTION_DATE=2022-10-03T00:00:00+00:00
AIRFLOW_CTX_TRY_NUMBER=1
AIRFLOW_CTX_DAG_RUN_ID=scheduled__2022-10-03T00:00:00+00:00
[2023-06-21 16:29:23,767] {subprocess.py:62} INFO - Tmp dir root location: 
 /tmp
[2023-06-21 16:29:23,767] {subprocess.py:74} INFO - Running command: ['bash', '-c', 'mkdir -p "/home/gilmar/Documentos/airflowalura/semana=2022-10-10"']
[2023-06-21 16:29:23,775] {subprocess.py:85} INFO - Output:
[2023-06-21 16:29:23,778] {subprocess.py:96} INFO - Command exited with return code 0
[2023-06-21 16:29:23,801] {taskinstance.py:1395} INFO - Marking task as SUCCESS. dag_id=dados_climaticos, task_id=cria_pasta, execution_date=20221003T000000, start_date=20230621T192923, end_date=20230621T192923
[2023-06-21 16:29:23,821] {local_task_job.py:156} INFO - Task exited with return code 0
[2023-06-21 16:29:23,845] {local_task_job.py:273} INFO - 1 downstream tasks scheduled from follow-on schedule check
[2023-06-21 16:31:02,777] {taskinstance.py:1159} INFO - Dependencies all met for <TaskInstance: dados_climaticos.cria_pasta scheduled__2022-10-03T00:00:00+00:00 [queued]>
[2023-06-21 16:31:02,782] {taskinstance.py:1159} INFO - Dependencies all met for <TaskInstance: dados_climaticos.cria_pasta scheduled__2022-10-03T00:00:00+00:00 [queued]>
[2023-06-21 16:31:02,782] {taskinstance.py:1356} INFO - 
--------------------------------------------------------------------------------
[2023-06-21 16:31:02,782] {taskinstance.py:1357} INFO - Starting attempt 1 of 1
[2023-06-21 16:31:02,782] {taskinstance.py:1358} INFO - 
--------------------------------------------------------------------------------
[2023-06-21 16:31:02,795] {taskinstance.py:1377} INFO - Executing <Task(BashOperator): cria_pasta> on 2022-10-03 00:00:00+00:00
[2023-06-21 16:31:02,799] {standard_task_runner.py:52} INFO - Started process 10163 to run task
[2023-06-21 16:31:02,802] {standard_task_runner.py:79} INFO - Running: ['airflow', 'tasks', 'run', 'dados_climaticos', 'cria_pasta', 'scheduled__2022-10-03T00:00:00+00:00', '--job-id', '76', '--raw', '--subdir', 'DAGS_FOLDER/dados_climaticos_OLD.py', '--cfg-path', '/tmp/tmpegq3damn', '--error-file', '/tmp/tmp0furohq6']
[2023-06-21 16:31:02,802] {standard_task_runner.py:80} INFO - Job 76: Subtask cria_pasta
[2023-06-21 16:31:02,831] {task_command.py:370} INFO - Running <TaskInstance: dados_climaticos.cria_pasta scheduled__2022-10-03T00:00:00+00:00 [running]> on host alura
[2023-06-21 16:31:02,848] {taskinstance.py:1889} ERROR - Task failed with exception
Traceback (most recent call last):
  File "/home/gilmar/Documentos/airflowalura/venv/lib/python3.9/site-packages/airflow/models/taskinstance.py", line 1451, in _run_raw_task
    self._execute_task_with_callbacks(context, test_mode)
  File "/home/gilmar/Documentos/airflowalura/venv/lib/python3.9/site-packages/airflow/models/taskinstance.py", line 1555, in _execute_task_with_callbacks
    task_orig = self.render_templates(context=context)
  File "/home/gilmar/Documentos/airflowalura/venv/lib/python3.9/site-packages/airflow/models/taskinstance.py", line 2212, in render_templates
    rendered_task = self.task.render_template_fields(context)
  File "/home/gilmar/Documentos/airflowalura/venv/lib/python3.9/site-packages/airflow/models/baseoperator.py", line 1185, in render_template_fields
    self._do_render_template_fields(self, self.template_fields, context, jinja_env, set())
  File "/home/gilmar/Documentos/airflowalura/venv/lib/python3.9/site-packages/airflow/utils/session.py", line 71, in wrapper
    return func(*args, session=session, **kwargs)
  File "/home/gilmar/Documentos/airflowalura/venv/lib/python3.9/site-packages/airflow/models/abstractoperator.py", line 344, in _do_render_template_fields
    rendered_content = self.render_template(
  File "/home/gilmar/Documentos/airflowalura/venv/lib/python3.9/site-packages/airflow/models/abstractoperator.py", line 387, in render_template
    template = jinja_env.from_string(value)
  File "/home/gilmar/Documentos/airflowalura/venv/lib/python3.9/site-packages/jinja2/environment.py", line 1092, in from_string
    return cls.from_code(self, self.compile(source), gs, None)
  File "/home/gilmar/Documentos/airflowalura/venv/lib/python3.9/site-packages/jinja2/environment.py", line 757, in compile
    self.handle_exception(source=source_hint)
  File "/home/gilmar/Documentos/airflowalura/venv/lib/python3.9/site-packages/jinja2/environment.py", line 925, in handle_exception
    raise rewrite_traceback_stack(source=source)
  File "<unknown>", line 1, in template
jinja2.exceptions.TemplateSyntaxError: unexpected end of template, expected ','.
[2023-06-21 16:31:02,851] {taskinstance.py:1395} INFO - Marking task as FAILED. dag_id=dados_climaticos, task_id=cria_pasta, execution_date=20221003T000000, start_date=20230621T193102, end_date=20230621T193102
[2023-06-21 16:31:02,860] {standard_task_runner.py:92} ERROR - Failed to execute job 76 for task cria_pasta (unexpected end of template, expected ','.; 10163)
[2023-06-21 16:31:02,897] {local_task_job.py:156} INFO - Task exited with return code 1
[2023-06-21 16:31:02,923] {local_task_job.py:273} INFO - 0 downstream tasks scheduled from follow-on schedule check
[2023-06-22 10:18:35,780] {taskinstance.py:1159} INFO - Dependencies all met for <TaskInstance: dados_climaticos.cria_pasta scheduled__2022-10-03T00:00:00+00:00 [queued]>
[2023-06-22 10:18:35,789] {taskinstance.py:1159} INFO - Dependencies all met for <TaskInstance: dados_climaticos.cria_pasta scheduled__2022-10-03T00:00:00+00:00 [queued]>
[2023-06-22 10:18:35,789] {taskinstance.py:1356} INFO - 
--------------------------------------------------------------------------------
[2023-06-22 10:18:35,790] {taskinstance.py:1357} INFO - Starting attempt 1 of 1
[2023-06-22 10:18:35,790] {taskinstance.py:1358} INFO - 
--------------------------------------------------------------------------------
[2023-06-22 10:18:35,803] {taskinstance.py:1377} INFO - Executing <Task(BashOperator): cria_pasta> on 2022-10-03 00:00:00+00:00
[2023-06-22 10:18:35,806] {standard_task_runner.py:52} INFO - Started process 8870 to run task
[2023-06-22 10:18:35,809] {standard_task_runner.py:79} INFO - Running: ['airflow', 'tasks', 'run', 'dados_climaticos', 'cria_pasta', 'scheduled__2022-10-03T00:00:00+00:00', '--job-id', '146', '--raw', '--subdir', 'DAGS_FOLDER/dados_climaticos_OLD.py', '--cfg-path', '/tmp/tmpeae3q0o3', '--error-file', '/tmp/tmp87ty5ws2']
[2023-06-22 10:18:35,810] {standard_task_runner.py:80} INFO - Job 146: Subtask cria_pasta
[2023-06-22 10:18:35,843] {task_command.py:370} INFO - Running <TaskInstance: dados_climaticos.cria_pasta scheduled__2022-10-03T00:00:00+00:00 [running]> on host alura
[2023-06-22 10:18:35,861] {taskinstance.py:1889} ERROR - Task failed with exception
Traceback (most recent call last):
  File "/home/gilmar/Documentos/airflowalura/venv/lib/python3.9/site-packages/airflow/models/taskinstance.py", line 1451, in _run_raw_task
    self._execute_task_with_callbacks(context, test_mode)
  File "/home/gilmar/Documentos/airflowalura/venv/lib/python3.9/site-packages/airflow/models/taskinstance.py", line 1555, in _execute_task_with_callbacks
    task_orig = self.render_templates(context=context)
  File "/home/gilmar/Documentos/airflowalura/venv/lib/python3.9/site-packages/airflow/models/taskinstance.py", line 2212, in render_templates
    rendered_task = self.task.render_template_fields(context)
  File "/home/gilmar/Documentos/airflowalura/venv/lib/python3.9/site-packages/airflow/models/baseoperator.py", line 1185, in render_template_fields
    self._do_render_template_fields(self, self.template_fields, context, jinja_env, set())
  File "/home/gilmar/Documentos/airflowalura/venv/lib/python3.9/site-packages/airflow/utils/session.py", line 71, in wrapper
    return func(*args, session=session, **kwargs)
  File "/home/gilmar/Documentos/airflowalura/venv/lib/python3.9/site-packages/airflow/models/abstractoperator.py", line 344, in _do_render_template_fields
    rendered_content = self.render_template(
  File "/home/gilmar/Documentos/airflowalura/venv/lib/python3.9/site-packages/airflow/models/abstractoperator.py", line 387, in render_template
    template = jinja_env.from_string(value)
  File "/home/gilmar/Documentos/airflowalura/venv/lib/python3.9/site-packages/jinja2/environment.py", line 1092, in from_string
    return cls.from_code(self, self.compile(source), gs, None)
  File "/home/gilmar/Documentos/airflowalura/venv/lib/python3.9/site-packages/jinja2/environment.py", line 757, in compile
    self.handle_exception(source=source_hint)
  File "/home/gilmar/Documentos/airflowalura/venv/lib/python3.9/site-packages/jinja2/environment.py", line 925, in handle_exception
    raise rewrite_traceback_stack(source=source)
  File "<unknown>", line 1, in template
jinja2.exceptions.TemplateSyntaxError: unexpected end of template, expected ','.
[2023-06-22 10:18:35,866] {taskinstance.py:1395} INFO - Marking task as FAILED. dag_id=dados_climaticos, task_id=cria_pasta, execution_date=20221003T000000, start_date=20230622T131835, end_date=20230622T131835
[2023-06-22 10:18:35,875] {standard_task_runner.py:92} ERROR - Failed to execute job 146 for task cria_pasta (unexpected end of template, expected ','.; 8870)
[2023-06-22 10:18:35,904] {local_task_job.py:156} INFO - Task exited with return code 1
[2023-06-22 10:18:35,931] {local_task_job.py:273} INFO - 0 downstream tasks scheduled from follow-on schedule check
