[2023-06-21 16:35:41,729] {taskinstance.py:1159} INFO - Dependencies all met for <TaskInstance: dados_climaticos.extrai_dados scheduled__2023-01-16T00:00:00+00:00 [queued]>
[2023-06-21 16:35:41,733] {taskinstance.py:1159} INFO - Dependencies all met for <TaskInstance: dados_climaticos.extrai_dados scheduled__2023-01-16T00:00:00+00:00 [queued]>
[2023-06-21 16:35:41,733] {taskinstance.py:1356} INFO - 
--------------------------------------------------------------------------------
[2023-06-21 16:35:41,734] {taskinstance.py:1357} INFO - Starting attempt 1 of 1
[2023-06-21 16:35:41,734] {taskinstance.py:1358} INFO - 
--------------------------------------------------------------------------------
[2023-06-21 16:35:41,746] {taskinstance.py:1377} INFO - Executing <Task(PythonOperator): extrai_dados> on 2023-01-16 00:00:00+00:00
[2023-06-21 16:35:41,749] {standard_task_runner.py:52} INFO - Started process 11775 to run task
[2023-06-21 16:35:41,752] {standard_task_runner.py:79} INFO - Running: ['airflow', 'tasks', 'run', 'dados_climaticos', 'extrai_dados', 'scheduled__2023-01-16T00:00:00+00:00', '--job-id', '108', '--raw', '--subdir', 'DAGS_FOLDER/dados_climaticos_OLD.py', '--cfg-path', '/tmp/tmp90nr2aat', '--error-file', '/tmp/tmpzhtkudco']
[2023-06-21 16:35:41,753] {standard_task_runner.py:80} INFO - Job 108: Subtask extrai_dados
[2023-06-21 16:35:41,786] {task_command.py:370} INFO - Running <TaskInstance: dados_climaticos.extrai_dados scheduled__2023-01-16T00:00:00+00:00 [running]> on host alura
[2023-06-21 16:35:41,804] {taskinstance.py:1889} ERROR - Task failed with exception
Traceback (most recent call last):
  File "/home/gilmar/Documentos/airflowalura/venv/lib/python3.9/site-packages/airflow/models/taskinstance.py", line 1451, in _run_raw_task
    self._execute_task_with_callbacks(context, test_mode)
  File "/home/gilmar/Documentos/airflowalura/venv/lib/python3.9/site-packages/airflow/models/taskinstance.py", line 1555, in _execute_task_with_callbacks
    task_orig = self.render_templates(context=context)
  File "/home/gilmar/Documentos/airflowalura/venv/lib/python3.9/site-packages/airflow/models/taskinstance.py", line 2212, in render_templates
    rendered_task = self.task.render_template_fields(context)
  File "/home/gilmar/Documentos/airflowalura/venv/lib/python3.9/site-packages/airflow/models/baseoperator.py", line 1185, in render_template_fields
    self._do_render_template_fields(self, self.template_fields, context, jinja_env, set())
  File "/home/gilmar/Documentos/airflowalura/venv/lib/python3.9/site-packages/airflow/utils/session.py", line 71, in wrapper
    return func(*args, session=session, **kwargs)
  File "/home/gilmar/Documentos/airflowalura/venv/lib/python3.9/site-packages/airflow/models/abstractoperator.py", line 344, in _do_render_template_fields
    rendered_content = self.render_template(
  File "/home/gilmar/Documentos/airflowalura/venv/lib/python3.9/site-packages/airflow/models/abstractoperator.py", line 404, in render_template
    return {key: self.render_template(value, context, jinja_env) for key, value in value.items()}
  File "/home/gilmar/Documentos/airflowalura/venv/lib/python3.9/site-packages/airflow/models/abstractoperator.py", line 404, in <dictcomp>
    return {key: self.render_template(value, context, jinja_env) for key, value in value.items()}
  File "/home/gilmar/Documentos/airflowalura/venv/lib/python3.9/site-packages/airflow/models/abstractoperator.py", line 387, in render_template
    template = jinja_env.from_string(value)
  File "/home/gilmar/Documentos/airflowalura/venv/lib/python3.9/site-packages/jinja2/environment.py", line 1092, in from_string
    return cls.from_code(self, self.compile(source), gs, None)
  File "/home/gilmar/Documentos/airflowalura/venv/lib/python3.9/site-packages/jinja2/environment.py", line 757, in compile
    self.handle_exception(source=source_hint)
  File "/home/gilmar/Documentos/airflowalura/venv/lib/python3.9/site-packages/jinja2/environment.py", line 925, in handle_exception
    raise rewrite_traceback_stack(source=source)
  File "<unknown>", line 1, in template
jinja2.exceptions.TemplateSyntaxError: unexpected char '"' at 29
[2023-06-21 16:35:41,808] {taskinstance.py:1395} INFO - Marking task as FAILED. dag_id=dados_climaticos, task_id=extrai_dados, execution_date=20230116T000000, start_date=20230621T193541, end_date=20230621T193541
[2023-06-21 16:35:41,815] {standard_task_runner.py:92} ERROR - Failed to execute job 108 for task extrai_dados (unexpected char '"' at 29; 11775)
[2023-06-21 16:35:41,848] {local_task_job.py:156} INFO - Task exited with return code 1
[2023-06-21 16:35:41,868] {local_task_job.py:273} INFO - 0 downstream tasks scheduled from follow-on schedule check
