[2023-06-21 14:10:56,642] {taskinstance.py:1159} INFO - Dependencies all met for <TaskInstance: dados_climaticos.criar_pasta scheduled__2023-01-09T00:00:00+00:00 [queued]>
[2023-06-21 14:10:56,646] {taskinstance.py:1159} INFO - Dependencies all met for <TaskInstance: dados_climaticos.criar_pasta scheduled__2023-01-09T00:00:00+00:00 [queued]>
[2023-06-21 14:10:56,646] {taskinstance.py:1356} INFO - 
--------------------------------------------------------------------------------
[2023-06-21 14:10:56,646] {taskinstance.py:1357} INFO - Starting attempt 1 of 1
[2023-06-21 14:10:56,646] {taskinstance.py:1358} INFO - 
--------------------------------------------------------------------------------
[2023-06-21 14:10:56,655] {taskinstance.py:1377} INFO - Executing <Task(BashOperator): criar_pasta> on 2023-01-09 00:00:00+00:00
[2023-06-21 14:10:56,658] {standard_task_runner.py:52} INFO - Started process 87324 to run task
[2023-06-21 14:10:56,662] {standard_task_runner.py:79} INFO - Running: ['airflow', 'tasks', 'run', 'dados_climaticos', 'criar_pasta', 'scheduled__2023-01-09T00:00:00+00:00', '--job-id', '41', '--raw', '--subdir', 'DAGS_FOLDER/dados_climaticos.py', '--cfg-path', '/tmp/tmpumrk_7o3', '--error-file', '/tmp/tmpui79o8_z']
[2023-06-21 14:10:56,662] {standard_task_runner.py:80} INFO - Job 41: Subtask criar_pasta
[2023-06-21 14:10:56,698] {task_command.py:370} INFO - Running <TaskInstance: dados_climaticos.criar_pasta scheduled__2023-01-09T00:00:00+00:00 [running]> on host alura
[2023-06-21 14:10:56,718] {taskinstance.py:1889} ERROR - Task failed with exception
Traceback (most recent call last):
  File "/home/gilmar/Documentos/airflowalura/venv/lib/python3.9/site-packages/airflow/models/taskinstance.py", line 1451, in _run_raw_task
    self._execute_task_with_callbacks(context, test_mode)
  File "/home/gilmar/Documentos/airflowalura/venv/lib/python3.9/site-packages/airflow/models/taskinstance.py", line 1555, in _execute_task_with_callbacks
    task_orig = self.render_templates(context=context)
  File "/home/gilmar/Documentos/airflowalura/venv/lib/python3.9/site-packages/airflow/models/taskinstance.py", line 2212, in render_templates
    rendered_task = self.task.render_template_fields(context)
  File "/home/gilmar/Documentos/airflowalura/venv/lib/python3.9/site-packages/airflow/models/baseoperator.py", line 1185, in render_template_fields
    self._do_render_template_fields(self, self.template_fields, context, jinja_env, set())
  File "/home/gilmar/Documentos/airflowalura/venv/lib/python3.9/site-packages/airflow/utils/session.py", line 71, in wrapper
    return func(*args, session=session, **kwargs)
  File "/home/gilmar/Documentos/airflowalura/venv/lib/python3.9/site-packages/airflow/models/abstractoperator.py", line 344, in _do_render_template_fields
    rendered_content = self.render_template(
  File "/home/gilmar/Documentos/airflowalura/venv/lib/python3.9/site-packages/airflow/models/abstractoperator.py", line 387, in render_template
    template = jinja_env.from_string(value)
  File "/home/gilmar/Documentos/airflowalura/venv/lib/python3.9/site-packages/jinja2/environment.py", line 1092, in from_string
    return cls.from_code(self, self.compile(source), gs, None)
  File "/home/gilmar/Documentos/airflowalura/venv/lib/python3.9/site-packages/jinja2/environment.py", line 757, in compile
    self.handle_exception(source=source_hint)
  File "/home/gilmar/Documentos/airflowalura/venv/lib/python3.9/site-packages/jinja2/environment.py", line 925, in handle_exception
    raise rewrite_traceback_stack(source=source)
  File "<unknown>", line 1, in template
jinja2.exceptions.TemplateSyntaxError: unexpected end of template, expected ','.
[2023-06-21 14:10:56,721] {taskinstance.py:1395} INFO - Marking task as FAILED. dag_id=dados_climaticos, task_id=criar_pasta, execution_date=20230109T000000, start_date=20230621T171056, end_date=20230621T171056
[2023-06-21 14:10:56,728] {standard_task_runner.py:92} ERROR - Failed to execute job 41 for task criar_pasta (unexpected end of template, expected ','.; 87324)
[2023-06-21 14:10:56,757] {local_task_job.py:156} INFO - Task exited with return code 1
[2023-06-21 14:10:56,778] {local_task_job.py:273} INFO - 0 downstream tasks scheduled from follow-on schedule check
[2023-06-21 14:16:04,468] {taskinstance.py:1159} INFO - Dependencies all met for <TaskInstance: dados_climaticos.criar_pasta scheduled__2023-01-09T00:00:00+00:00 [queued]>
[2023-06-21 14:16:04,476] {taskinstance.py:1159} INFO - Dependencies all met for <TaskInstance: dados_climaticos.criar_pasta scheduled__2023-01-09T00:00:00+00:00 [queued]>
[2023-06-21 14:16:04,476] {taskinstance.py:1356} INFO - 
--------------------------------------------------------------------------------
[2023-06-21 14:16:04,476] {taskinstance.py:1357} INFO - Starting attempt 1 of 1
[2023-06-21 14:16:04,476] {taskinstance.py:1358} INFO - 
--------------------------------------------------------------------------------
[2023-06-21 14:16:04,489] {taskinstance.py:1377} INFO - Executing <Task(BashOperator): criar_pasta> on 2023-01-09 00:00:00+00:00
[2023-06-21 14:16:04,495] {standard_task_runner.py:52} INFO - Started process 87865 to run task
[2023-06-21 14:16:04,499] {standard_task_runner.py:79} INFO - Running: ['airflow', 'tasks', 'run', 'dados_climaticos', 'criar_pasta', 'scheduled__2023-01-09T00:00:00+00:00', '--job-id', '41', '--raw', '--subdir', 'DAGS_FOLDER/dados_climaticos.py', '--cfg-path', '/tmp/tmprodduz75', '--error-file', '/tmp/tmp7wpdpjwz']
[2023-06-21 14:16:04,500] {standard_task_runner.py:80} INFO - Job 41: Subtask criar_pasta
[2023-06-21 14:16:04,554] {task_command.py:370} INFO - Running <TaskInstance: dados_climaticos.criar_pasta scheduled__2023-01-09T00:00:00+00:00 [running]> on host alura
[2023-06-21 14:16:04,579] {taskinstance.py:1889} ERROR - Task failed with exception
Traceback (most recent call last):
  File "/home/gilmar/Documentos/airflowalura/venv/lib/python3.9/site-packages/airflow/models/taskinstance.py", line 1451, in _run_raw_task
    self._execute_task_with_callbacks(context, test_mode)
  File "/home/gilmar/Documentos/airflowalura/venv/lib/python3.9/site-packages/airflow/models/taskinstance.py", line 1555, in _execute_task_with_callbacks
    task_orig = self.render_templates(context=context)
  File "/home/gilmar/Documentos/airflowalura/venv/lib/python3.9/site-packages/airflow/models/taskinstance.py", line 2212, in render_templates
    rendered_task = self.task.render_template_fields(context)
  File "/home/gilmar/Documentos/airflowalura/venv/lib/python3.9/site-packages/airflow/models/baseoperator.py", line 1185, in render_template_fields
    self._do_render_template_fields(self, self.template_fields, context, jinja_env, set())
  File "/home/gilmar/Documentos/airflowalura/venv/lib/python3.9/site-packages/airflow/utils/session.py", line 71, in wrapper
    return func(*args, session=session, **kwargs)
  File "/home/gilmar/Documentos/airflowalura/venv/lib/python3.9/site-packages/airflow/models/abstractoperator.py", line 344, in _do_render_template_fields
    rendered_content = self.render_template(
  File "/home/gilmar/Documentos/airflowalura/venv/lib/python3.9/site-packages/airflow/models/abstractoperator.py", line 387, in render_template
    template = jinja_env.from_string(value)
  File "/home/gilmar/Documentos/airflowalura/venv/lib/python3.9/site-packages/jinja2/environment.py", line 1092, in from_string
    return cls.from_code(self, self.compile(source), gs, None)
  File "/home/gilmar/Documentos/airflowalura/venv/lib/python3.9/site-packages/jinja2/environment.py", line 757, in compile
    self.handle_exception(source=source_hint)
  File "/home/gilmar/Documentos/airflowalura/venv/lib/python3.9/site-packages/jinja2/environment.py", line 925, in handle_exception
    raise rewrite_traceback_stack(source=source)
  File "<unknown>", line 1, in template
jinja2.exceptions.TemplateSyntaxError: unexpected end of template, expected ','.
[2023-06-21 14:16:04,583] {taskinstance.py:1395} INFO - Marking task as FAILED. dag_id=dados_climaticos, task_id=criar_pasta, execution_date=20230109T000000, start_date=20230621T171604, end_date=20230621T171604
[2023-06-21 14:16:04,593] {standard_task_runner.py:92} ERROR - Failed to execute job 41 for task criar_pasta (unexpected end of template, expected ','.; 87865)
[2023-06-21 14:16:04,598] {local_task_job.py:156} INFO - Task exited with return code 1
[2023-06-21 14:16:04,622] {local_task_job.py:273} INFO - 0 downstream tasks scheduled from follow-on schedule check
