[2023-06-21 16:29:19,315] {taskinstance.py:1159} INFO - Dependencies all met for <TaskInstance: dados_climaticos.cria_pasta scheduled__2022-09-26T00:00:00+00:00 [queued]>
[2023-06-21 16:29:19,319] {taskinstance.py:1159} INFO - Dependencies all met for <TaskInstance: dados_climaticos.cria_pasta scheduled__2022-09-26T00:00:00+00:00 [queued]>
[2023-06-21 16:29:19,319] {taskinstance.py:1356} INFO - 
--------------------------------------------------------------------------------
[2023-06-21 16:29:19,319] {taskinstance.py:1357} INFO - Starting attempt 1 of 1
[2023-06-21 16:29:19,319] {taskinstance.py:1358} INFO - 
--------------------------------------------------------------------------------
[2023-06-21 16:29:19,330] {taskinstance.py:1377} INFO - Executing <Task(BashOperator): cria_pasta> on 2022-09-26 00:00:00+00:00
[2023-06-21 16:29:19,333] {standard_task_runner.py:52} INFO - Started process 9518 to run task
[2023-06-21 16:29:19,336] {standard_task_runner.py:79} INFO - Running: ['airflow', 'tasks', 'run', 'dados_climaticos', 'cria_pasta', 'scheduled__2022-09-26T00:00:00+00:00', '--job-id', '78', '--raw', '--subdir', 'DAGS_FOLDER/dados_climaticos.py', '--cfg-path', '/tmp/tmpei3iyvym', '--error-file', '/tmp/tmpdws9qcre']
[2023-06-21 16:29:19,337] {standard_task_runner.py:80} INFO - Job 78: Subtask cria_pasta
[2023-06-21 16:29:19,375] {task_command.py:370} INFO - Running <TaskInstance: dados_climaticos.cria_pasta scheduled__2022-09-26T00:00:00+00:00 [running]> on host alura
[2023-06-21 16:29:19,414] {taskinstance.py:1569} INFO - Exporting the following env vars:
AIRFLOW_CTX_DAG_OWNER=airflow
AIRFLOW_CTX_DAG_ID=dados_climaticos
AIRFLOW_CTX_TASK_ID=cria_pasta
AIRFLOW_CTX_EXECUTION_DATE=2022-09-26T00:00:00+00:00
AIRFLOW_CTX_TRY_NUMBER=1
AIRFLOW_CTX_DAG_RUN_ID=scheduled__2022-09-26T00:00:00+00:00
[2023-06-21 16:29:19,415] {subprocess.py:62} INFO - Tmp dir root location: 
 /tmp
[2023-06-21 16:29:19,416] {subprocess.py:74} INFO - Running command: ['bash', '-c', 'mkdir -p "/home/gilmar/Documentos/airflowalura/semana=2022-10-03"']
[2023-06-21 16:29:19,425] {subprocess.py:85} INFO - Output:
[2023-06-21 16:29:19,428] {subprocess.py:96} INFO - Command exited with return code 0
[2023-06-21 16:29:19,444] {taskinstance.py:1395} INFO - Marking task as SUCCESS. dag_id=dados_climaticos, task_id=cria_pasta, execution_date=20220926T000000, start_date=20230621T192919, end_date=20230621T192919
[2023-06-21 16:29:19,473] {local_task_job.py:156} INFO - Task exited with return code 0
[2023-06-21 16:29:19,499] {local_task_job.py:273} INFO - 1 downstream tasks scheduled from follow-on schedule check
[2023-06-21 16:31:00,497] {taskinstance.py:1159} INFO - Dependencies all met for <TaskInstance: dados_climaticos.cria_pasta scheduled__2022-09-26T00:00:00+00:00 [queued]>
[2023-06-21 16:31:00,501] {taskinstance.py:1159} INFO - Dependencies all met for <TaskInstance: dados_climaticos.cria_pasta scheduled__2022-09-26T00:00:00+00:00 [queued]>
[2023-06-21 16:31:00,501] {taskinstance.py:1356} INFO - 
--------------------------------------------------------------------------------
[2023-06-21 16:31:00,501] {taskinstance.py:1357} INFO - Starting attempt 1 of 1
[2023-06-21 16:31:00,501] {taskinstance.py:1358} INFO - 
--------------------------------------------------------------------------------
[2023-06-21 16:31:00,510] {taskinstance.py:1377} INFO - Executing <Task(BashOperator): cria_pasta> on 2022-09-26 00:00:00+00:00
[2023-06-21 16:31:00,513] {standard_task_runner.py:52} INFO - Started process 10145 to run task
[2023-06-21 16:31:00,516] {standard_task_runner.py:79} INFO - Running: ['airflow', 'tasks', 'run', 'dados_climaticos', 'cria_pasta', 'scheduled__2022-09-26T00:00:00+00:00', '--job-id', '75', '--raw', '--subdir', 'DAGS_FOLDER/dados_climaticos_OLD.py', '--cfg-path', '/tmp/tmpr84v1kt_', '--error-file', '/tmp/tmpzmq_9r28']
[2023-06-21 16:31:00,517] {standard_task_runner.py:80} INFO - Job 75: Subtask cria_pasta
[2023-06-21 16:31:00,546] {task_command.py:370} INFO - Running <TaskInstance: dados_climaticos.cria_pasta scheduled__2022-09-26T00:00:00+00:00 [running]> on host alura
[2023-06-21 16:31:00,563] {taskinstance.py:1889} ERROR - Task failed with exception
Traceback (most recent call last):
  File "/home/gilmar/Documentos/airflowalura/venv/lib/python3.9/site-packages/airflow/models/taskinstance.py", line 1451, in _run_raw_task
    self._execute_task_with_callbacks(context, test_mode)
  File "/home/gilmar/Documentos/airflowalura/venv/lib/python3.9/site-packages/airflow/models/taskinstance.py", line 1555, in _execute_task_with_callbacks
    task_orig = self.render_templates(context=context)
  File "/home/gilmar/Documentos/airflowalura/venv/lib/python3.9/site-packages/airflow/models/taskinstance.py", line 2212, in render_templates
    rendered_task = self.task.render_template_fields(context)
  File "/home/gilmar/Documentos/airflowalura/venv/lib/python3.9/site-packages/airflow/models/baseoperator.py", line 1185, in render_template_fields
    self._do_render_template_fields(self, self.template_fields, context, jinja_env, set())
  File "/home/gilmar/Documentos/airflowalura/venv/lib/python3.9/site-packages/airflow/utils/session.py", line 71, in wrapper
    return func(*args, session=session, **kwargs)
  File "/home/gilmar/Documentos/airflowalura/venv/lib/python3.9/site-packages/airflow/models/abstractoperator.py", line 344, in _do_render_template_fields
    rendered_content = self.render_template(
  File "/home/gilmar/Documentos/airflowalura/venv/lib/python3.9/site-packages/airflow/models/abstractoperator.py", line 387, in render_template
    template = jinja_env.from_string(value)
  File "/home/gilmar/Documentos/airflowalura/venv/lib/python3.9/site-packages/jinja2/environment.py", line 1092, in from_string
    return cls.from_code(self, self.compile(source), gs, None)
  File "/home/gilmar/Documentos/airflowalura/venv/lib/python3.9/site-packages/jinja2/environment.py", line 757, in compile
    self.handle_exception(source=source_hint)
  File "/home/gilmar/Documentos/airflowalura/venv/lib/python3.9/site-packages/jinja2/environment.py", line 925, in handle_exception
    raise rewrite_traceback_stack(source=source)
  File "<unknown>", line 1, in template
jinja2.exceptions.TemplateSyntaxError: unexpected end of template, expected ','.
[2023-06-21 16:31:00,566] {taskinstance.py:1395} INFO - Marking task as FAILED. dag_id=dados_climaticos, task_id=cria_pasta, execution_date=20220926T000000, start_date=20230621T193100, end_date=20230621T193100
[2023-06-21 16:31:00,573] {standard_task_runner.py:92} ERROR - Failed to execute job 75 for task cria_pasta (unexpected end of template, expected ','.; 10145)
[2023-06-21 16:31:00,611] {local_task_job.py:156} INFO - Task exited with return code 1
[2023-06-21 16:31:00,633] {local_task_job.py:273} INFO - 0 downstream tasks scheduled from follow-on schedule check
[2023-06-22 10:18:33,659] {taskinstance.py:1159} INFO - Dependencies all met for <TaskInstance: dados_climaticos.cria_pasta scheduled__2022-09-26T00:00:00+00:00 [queued]>
[2023-06-22 10:18:33,666] {taskinstance.py:1159} INFO - Dependencies all met for <TaskInstance: dados_climaticos.cria_pasta scheduled__2022-09-26T00:00:00+00:00 [queued]>
[2023-06-22 10:18:33,666] {taskinstance.py:1356} INFO - 
--------------------------------------------------------------------------------
[2023-06-22 10:18:33,667] {taskinstance.py:1357} INFO - Starting attempt 1 of 1
[2023-06-22 10:18:33,667] {taskinstance.py:1358} INFO - 
--------------------------------------------------------------------------------
[2023-06-22 10:18:33,676] {taskinstance.py:1377} INFO - Executing <Task(BashOperator): cria_pasta> on 2022-09-26 00:00:00+00:00
[2023-06-22 10:18:33,679] {standard_task_runner.py:52} INFO - Started process 8851 to run task
[2023-06-22 10:18:33,682] {standard_task_runner.py:79} INFO - Running: ['airflow', 'tasks', 'run', 'dados_climaticos', 'cria_pasta', 'scheduled__2022-09-26T00:00:00+00:00', '--job-id', '145', '--raw', '--subdir', 'DAGS_FOLDER/dados_climaticos_OLD.py', '--cfg-path', '/tmp/tmpevisia7v', '--error-file', '/tmp/tmp9qhsplwm']
[2023-06-22 10:18:33,683] {standard_task_runner.py:80} INFO - Job 145: Subtask cria_pasta
[2023-06-22 10:18:33,717] {task_command.py:370} INFO - Running <TaskInstance: dados_climaticos.cria_pasta scheduled__2022-09-26T00:00:00+00:00 [running]> on host alura
[2023-06-22 10:18:33,736] {taskinstance.py:1889} ERROR - Task failed with exception
Traceback (most recent call last):
  File "/home/gilmar/Documentos/airflowalura/venv/lib/python3.9/site-packages/airflow/models/taskinstance.py", line 1451, in _run_raw_task
    self._execute_task_with_callbacks(context, test_mode)
  File "/home/gilmar/Documentos/airflowalura/venv/lib/python3.9/site-packages/airflow/models/taskinstance.py", line 1555, in _execute_task_with_callbacks
    task_orig = self.render_templates(context=context)
  File "/home/gilmar/Documentos/airflowalura/venv/lib/python3.9/site-packages/airflow/models/taskinstance.py", line 2212, in render_templates
    rendered_task = self.task.render_template_fields(context)
  File "/home/gilmar/Documentos/airflowalura/venv/lib/python3.9/site-packages/airflow/models/baseoperator.py", line 1185, in render_template_fields
    self._do_render_template_fields(self, self.template_fields, context, jinja_env, set())
  File "/home/gilmar/Documentos/airflowalura/venv/lib/python3.9/site-packages/airflow/utils/session.py", line 71, in wrapper
    return func(*args, session=session, **kwargs)
  File "/home/gilmar/Documentos/airflowalura/venv/lib/python3.9/site-packages/airflow/models/abstractoperator.py", line 344, in _do_render_template_fields
    rendered_content = self.render_template(
  File "/home/gilmar/Documentos/airflowalura/venv/lib/python3.9/site-packages/airflow/models/abstractoperator.py", line 387, in render_template
    template = jinja_env.from_string(value)
  File "/home/gilmar/Documentos/airflowalura/venv/lib/python3.9/site-packages/jinja2/environment.py", line 1092, in from_string
    return cls.from_code(self, self.compile(source), gs, None)
  File "/home/gilmar/Documentos/airflowalura/venv/lib/python3.9/site-packages/jinja2/environment.py", line 757, in compile
    self.handle_exception(source=source_hint)
  File "/home/gilmar/Documentos/airflowalura/venv/lib/python3.9/site-packages/jinja2/environment.py", line 925, in handle_exception
    raise rewrite_traceback_stack(source=source)
  File "<unknown>", line 1, in template
jinja2.exceptions.TemplateSyntaxError: unexpected end of template, expected ','.
[2023-06-22 10:18:33,741] {taskinstance.py:1395} INFO - Marking task as FAILED. dag_id=dados_climaticos, task_id=cria_pasta, execution_date=20220926T000000, start_date=20230622T131833, end_date=20230622T131833
[2023-06-22 10:18:33,751] {standard_task_runner.py:92} ERROR - Failed to execute job 145 for task cria_pasta (unexpected end of template, expected ','.; 8851)
[2023-06-22 10:18:33,779] {local_task_job.py:156} INFO - Task exited with return code 1
[2023-06-22 10:18:33,809] {local_task_job.py:273} INFO - 0 downstream tasks scheduled from follow-on schedule check
